<sdf version='1.7'>
  <world name='corridor'>
    <plugin name='ActorPosesPlugin' filename='libActorPosesPlugin.so'/>
    <physics type='ode'>
      <max_step_size>0.004</max_step_size>
      <real_time_update_rate>250</real_time_update_rate>
      <real_time_factor>1</real_time_factor>
    </physics>
    <gravity>0 0 -9.8</gravity>
    <scene>
      <ambient>0.6 0.6 0.6 1</ambient>
      <background>0.7 0.7 0.7 1</background>
      <shadows>0</shadows>
    </scene>
    <light name='sun' type='directional'>
      <cast_shadows>0</cast_shadows>
      <pose>0 0 10 0 -0 0</pose>
      <diffuse>0.9 0.9 0.9 1</diffuse>
      <specular>0.1 0.1 0.1 1</specular>
      <direction>-0.5 0.1 -0.9</direction>
      <attenuation>
        <range>10</range>
      </attenuation>
      <spot>
        <inner_angle>0</inner_angle>
        <outer_angle>0</outer_angle>
        <falloff>0</falloff>
      </spot>
    </light>
    <model name='wall_top'>
      <static>1</static>
      <pose>-1.5 1.35 1.25 0 -0 0</pose>
      <link name='link'>
        <collision name='collision'>
          <geometry>
            <box>
              <size>13 0.2 2.5</size>
            </box>
          </geometry>
          <max_contacts>10</max_contacts>
          <surface>
            <contact>
              <ode/>
            </contact>
            <bounce/>
            <friction>
              <torsional>
                <ode/>
              </torsional>
              <ode/>
            </friction>
          </surface>
        </collision>
        <visual name='visual'>
          <geometry>
            <box>
              <size>13 0.2 2.5</size>
            </box>
          </geometry>
          <material>
            <ambient>0.4 0.4 0.4 1</ambient>
            <diffuse>0.4 0.4 0.4 1</diffuse>
          </material>
        </visual>
        <self_collide>0</self_collide>
        <enable_wind>0</enable_wind>
        <kinematic>0</kinematic>
      </link>
    </model>
    <model name='wall_bottom_left'>
      <static>1</static>
      <pose>-4.675 -1.35 1.25 0 -0 0</pose>
      <link name='link'>
        <collision name='collision'>
          <geometry>
            <box>
              <size>6.65 0.2 2.5</size>
            </box>
          </geometry>
          <max_contacts>10</max_contacts>
          <surface>
            <contact>
              <ode/>
            </contact>
            <bounce/>
            <friction>
              <torsional>
                <ode/>
              </torsional>
              <ode/>
            </friction>
          </surface>
        </collision>
        <visual name='visual'>
          <geometry>
            <box>
              <size>6.65 0.2 2.5</size>
            </box>
          </geometry>
          <material>
            <ambient>0.4 0.4 0.4 1</ambient>
            <diffuse>0.4 0.4 0.4 1</diffuse>
          </material>
        </visual>
        <self_collide>0</self_collide>
        <enable_wind>0</enable_wind>
        <kinematic>0</kinematic>
      </link>
    </model>
    <model name='wall_bottom_right'>
      <static>1</static>
      <pose>3.175 -1.35 1.25 0 -0 0</pose>
      <link name='link'>
        <collision name='collision'>
          <geometry>
            <box>
              <size>3.65 0.2 2.5</size>
            </box>
          </geometry>
          <max_contacts>10</max_contacts>
          <surface>
            <contact>
              <ode/>
            </contact>
            <bounce/>
            <friction>
              <torsional>
                <ode/>
              </torsional>
              <ode/>
            </friction>
          </surface>
        </collision>
        <visual name='visual'>
          <geometry>
            <box>
              <size>3.65 0.2 2.5</size>
            </box>
          </geometry>
          <material>
            <ambient>0.4 0.4 0.4 1</ambient>
            <diffuse>0.4 0.4 0.4 1</diffuse>
          </material>
        </visual>
        <self_collide>0</self_collide>
        <enable_wind>0</enable_wind>
        <kinematic>0</kinematic>
      </link>
    </model>
    <model name='wall_end_left'>
      <static>1</static>
      <pose>-8 0 1.25 0 -0 0</pose>
      <link name='link'>
        <collision name='collision'>
          <geometry>
            <box>
              <size>0.2 2.7 2.5</size>
            </box>
          </geometry>
          <max_contacts>10</max_contacts>
          <surface>
            <contact>
              <ode/>
            </contact>
            <bounce/>
            <friction>
              <torsional>
                <ode/>
              </torsional>
              <ode/>
            </friction>
          </surface>
        </collision>
        <visual name='visual'>
          <geometry>
            <box>
              <size>0.2 2.7 2.5</size>
            </box>
          </geometry>
          <material>
            <ambient>0.4 0.4 0.4 1</ambient>
            <diffuse>0.4 0.4 0.4 1</diffuse>
          </material>
        </visual>
        <self_collide>0</self_collide>
        <enable_wind>0</enable_wind>
        <kinematic>0</kinematic>
      </link>
    </model>
    <model name='wall_end_right'>
      <static>1</static>
      <pose>5 0 1.25 0 -0 0</pose>
      <link name='link'>
        <collision name='collision'>
          <geometry>
            <box>
              <size>0.2 2.7 2.5</size>
            </box>
          </geometry>
          <max_contacts>10</max_contacts>
          <surface>
            <contact>
              <ode/>
            </contact>
            <bounce/>
            <friction>
              <torsional>
                <ode/>
              </torsional>
              <ode/>
            </friction>
          </surface>
        </collision>
        <visual name='visual'>
          <geometry>
            <box>
              <size>0.2 2.7 2.5</size>
            </box>
          </geometry>
          <material>
            <ambient>0.4 0.4 0.4 1</ambient>
            <diffuse>0.4 0.4 0.4 1</diffuse>
          </material>
        </visual>
        <self_collide>0</self_collide>
        <enable_wind>0</enable_wind>
        <kinematic>0</kinematic>
      </link>
    </model>
    <model name='wall_vert_left'>
      <static>1</static>
      <pose>-1.35 -5.675 1.25 0 -0 0</pose>
      <link name='link'>
        <collision name='collision'>
          <geometry>
            <box>
              <size>0.2 8.65 2.5</size>
            </box>
          </geometry>
          <max_contacts>10</max_contacts>
          <surface>
            <contact>
              <ode/>
            </contact>
            <bounce/>
            <friction>
              <torsional>
                <ode/>
              </torsional>
              <ode/>
            </friction>
          </surface>
        </collision>
        <visual name='visual'>
          <geometry>
            <box>
              <size>0.2 8.65 2.5</size>
            </box>
          </geometry>
          <material>
            <ambient>0.4 0.4 0.4 1</ambient>
            <diffuse>0.4 0.4 0.4 1</diffuse>
          </material>
        </visual>
        <self_collide>0</self_collide>
        <enable_wind>0</enable_wind>
        <kinematic>0</kinematic>
      </link>
    </model>
    <model name='wall_vert_right'>
      <static>1</static>
      <pose>1.35 -5.675 1.25 0 -0 0</pose>
      <link name='link'>
        <collision name='collision'>
          <geometry>
            <box>
              <size>0.2 8.65 2.5</size>
            </box>
          </geometry>
          <max_contacts>10</max_contacts>
          <surface>
            <contact>
              <ode/>
            </contact>
            <bounce/>
            <friction>
              <torsional>
                <ode/>
              </torsional>
              <ode/>
            </friction>
          </surface>
        </collision>
        <visual name='visual'>
          <geometry>
            <box>
              <size>0.2 8.65 2.5</size>
            </box>
          </geometry>
          <material>
            <ambient>0.4 0.4 0.4 1</ambient>
            <diffuse>0.4 0.4 0.4 1</diffuse>
          </material>
        </visual>
        <self_collide>0</self_collide>
        <enable_wind>0</enable_wind>
        <kinematic>0</kinematic>
      </link>
    </model>
    <model name='wall_vert_bottom'>
      <static>1</static>
      <pose>0 -10 1.25 0 -0 0</pose>
      <link name='link'>
        <collision name='collision'>
          <geometry>
            <box>
              <size>2.7 0.2 2.5</size>
            </box>
          </geometry>
          <max_contacts>10</max_contacts>
          <surface>
            <contact>
              <ode/>
            </contact>
            <bounce/>
            <friction>
              <torsional>
                <ode/>
              </torsional>
              <ode/>
            </friction>
          </surface>
        </collision>
        <visual name='visual'>
          <geometry>
            <box>
              <size>2.7 0.2 2.5</size>
            </box>
          </geometry>
          <material>
            <ambient>0.4 0.4 0.4 1</ambient>
            <diffuse>0.4 0.4 0.4 1</diffuse>
          </material>
        </visual>
        <self_collide>0</self_collide>
        <enable_wind>0</enable_wind>
        <kinematic>0</kinematic>
      </link>
    </model>
    <magnetic_field>6e-06 2.3e-05 -4.2e-05</magnetic_field>
    <atmosphere type='adiabatic'/>
    <wind/>
    <spherical_coordinates>
      <surface_model>EARTH_WGS84</surface_model>
      <latitude_deg>0</latitude_deg>
      <longitude_deg>0</longitude_deg>
      <elevation>0</elevation>
      <heading_deg>0</heading_deg>
    </spherical_coordinates>
    <model name='tiago'>
      <link name='base_footprint'>
        <inertial>
          <pose>-0.00978 -0.00152 0.213783 0 -0 0</pose>
          <mass>42.8506</mass>
          <inertia>
            <ixx>2.01958</ixx>
            <ixy>0.00074088</ixy>
            <ixz>0.109957</ixz>
            <iyy>2.0976</iyy>
            <iyz>0.0139293</iyz>
            <izz>0.666852</izz>
          </inertia>
        </inertial>
        <collision name='base_footprint_fixed_joint_lump__base_link_collision'>
          <pose>0 0 0.0985 0 -0 0</pose>
          <geometry>
            <mesh>
              <scale>1 1 1</scale>
              <uri>/home/hrisim/tiago_ws/src/pmb2_robot/pmb2_description/meshes/base/base_collision.stl</uri>
            </mesh>
          </geometry>
          <surface>
            <contact>
              <ode/>
            </contact>
            <friction>
              <ode/>
              <torsional>
                <ode/>
              </torsional>
            </friction>
            <bounce/>
          </surface>
          <max_contacts>10</max_contacts>
        </collision>
        <collision name='base_footprint_fixed_joint_lump__base_antenna_left_link_collision_1'>
          <pose>-0.201 0.1062 0.3785 0 -0 0</pose>
          <geometry>
            <cylinder>
              <length>0.17</length>
              <radius>0.005</radius>
            </cylinder>
          </geometry>
          <surface>
            <contact>
              <ode/>
            </contact>
            <friction>
              <ode/>
              <torsional>
                <ode/>
              </torsional>
            </friction>
            <bounce/>
          </surface>
          <max_contacts>10</max_contacts>
        </collision>
        <collision name='base_footprint_fixed_joint_lump__base_antenna_right_link_collision_2'>
          <pose>-0.201 -0.1062 0.3785 0 -0 0</pose>
          <geometry>
            <cylinder>
              <length>0.17</length>
              <radius>0.005</radius>
            </cylinder>
          </geometry>
          <surface>
            <contact>
              <ode/>
            </contact>
            <friction>
              <ode/>
              <torsional>
                <ode/>
              </torsional>
            </friction>
            <bounce/>
          </surface>
          <max_contacts>10</max_contacts>
        </collision>
        <collision name='base_footprint_fixed_joint_lump__base_laser_link_collision_3'>
          <pose>0.202 0 0.0945 0 -0 0</pose>
          <geometry>
            <cylinder>
              <length>0.04</length>
              <radius>0.02</radius>
            </cylinder>
          </geometry>
          <surface>
            <contact>
              <ode/>
            </contact>
            <friction>
              <ode/>
              <torsional>
                <ode/>
              </torsional>
            </friction>
            <bounce/>
          </surface>
          <max_contacts>10</max_contacts>
        </collision>
        <collision name='base_footprint_fixed_joint_lump__torso_fixed_column_link_collision_4'>
          <pose>-0.062 0 0.5685 0 -0 0</pose>
          <geometry>
            <box>
              <size>0.23 0.253 0.45</size>
            </box>
          </geometry>
          <surface>
            <contact>
              <ode/>
            </contact>
            <friction>
              <ode/>
              <torsional>
                <ode/>
              </torsional>
            </friction>
            <bounce/>
          </surface>
          <max_contacts>10</max_contacts>
        </collision>
        <collision name='base_footprint_fixed_joint_lump__torso_fixed_link_collision_5'>
          <pose>0.028 0 0.3115 0 -0 0</pose>
          <geometry>
            <box>
              <size>0.4 0.28 0.075</size>
            </box>
          </geometry>
          <max_contacts>10</max_contacts>
          <surface>
            <contact>
              <ode/>
            </contact>
            <bounce/>
            <friction>
              <torsional>
                <ode/>
              </torsional>
              <ode/>
            </friction>
          </surface>
        </collision>
        <collision name='base_footprint_fixed_joint_lump__torso_fixed_link_collision_6'>
          <pose>-0.062 0 0.3415 0 -0 0</pose>
          <geometry>
            <box>
              <size>0.255 0.255 0.117</size>
            </box>
          </geometry>
          <max_contacts>10</max_contacts>
          <surface>
            <contact>
              <ode/>
            </contact>
            <bounce/>
            <friction>
              <torsional>
                <ode/>
              </torsional>
              <ode/>
            </friction>
          </surface>
        </collision>
        <visual name='base_footprint_fixed_joint_lump__base_link_visual'>
          <pose>0 0 0.0985 0 -0 0</pose>
          <geometry>
            <mesh>
              <scale>1 1 1</scale>
              <uri>/home/hrisim/tiago_ws/src/pmb2_robot/pmb2_description/meshes/base/base.stl</uri>
            </mesh>
          </geometry>
          <material>
            <script>
              <name>Gazebo/DarkGrey</name>
              <uri>file://media/materials/scripts/gazebo.material</uri>
            </script>
          </material>
        </visual>
        <visual name='base_footprint_fixed_joint_lump__base_antenna_left_link_visual_1'>
          <pose>-0.201 0.1062 0.2935 0 -0 0</pose>
          <geometry>
            <mesh>
              <scale>1 1 1</scale>
              <uri>/home/hrisim/tiago_ws/src/pmb2_robot/pmb2_description/meshes/objects/antenna.stl</uri>
            </mesh>
          </geometry>
          <material>
            <script>
              <name>Gazebo/Black</name>
              <uri>file://media/materials/scripts/gazebo.material</uri>
            </script>
          </material>
        </visual>
        <visual name='base_footprint_fixed_joint_lump__base_antenna_right_link_visual_2'>
          <pose>-0.201 -0.1062 0.2935 0 -0 0</pose>
          <geometry>
            <mesh>
              <scale>1 1 1</scale>
              <uri>/home/hrisim/tiago_ws/src/pmb2_robot/pmb2_description/meshes/objects/antenna.stl</uri>
            </mesh>
          </geometry>
          <material>
            <script>
              <name>Gazebo/Black</name>
              <uri>file://media/materials/scripts/gazebo.material</uri>
            </script>
          </material>
        </visual>
        <visual name='base_footprint_fixed_joint_lump__base_laser_link_visual_3'>
          <pose>0.202 0 0.0945 0 -0 0</pose>
          <geometry>
            <mesh>
              <scale>1 1 1</scale>
              <uri>/home/hrisim/tiago_ws/src/pmb2_robot/pmb2_description/meshes/sensors/sick_tim551.stl</uri>
            </mesh>
          </geometry>
          <material>
            <script>
              <name>Gazebo/DarkGrey</name>
              <uri>file://media/materials/scripts/gazebo.material</uri>
            </script>
          </material>
        </visual>
        <visual name='base_footprint_fixed_joint_lump__base_sonar_01_link_visual_4'>
          <pose>-0.183 -0.183 0.2715 0 0 -2.35619</pose>
          <geometry>
            <mesh>
              <scale>1 1 1</scale>
              <uri>/home/hrisim/tiago_ws/src/pmb2_robot/pmb2_description/meshes/sensors/srf05.stl</uri>
            </mesh>
          </geometry>
          <material>
            <script>
              <name>Gazebo/DarkGrey</name>
              <uri>file://media/materials/scripts/gazebo.material</uri>
            </script>
          </material>
        </visual>
        <visual name='base_footprint_fixed_joint_lump__base_sonar_02_link_visual_5'>
          <pose>-0.259 0 0.2715 0 -0 3.14159</pose>
          <geometry>
            <mesh>
              <scale>1 1 1</scale>
              <uri>/home/hrisim/tiago_ws/src/pmb2_robot/pmb2_description/meshes/sensors/srf05.stl</uri>
            </mesh>
          </geometry>
          <material>
            <script>
              <name>Gazebo/DarkGrey</name>
              <uri>file://media/materials/scripts/gazebo.material</uri>
            </script>
          </material>
        </visual>
        <visual name='base_footprint_fixed_joint_lump__base_sonar_03_link_visual_6'>
          <pose>-0.183 0.183 0.2715 0 -0 2.35619</pose>
          <geometry>
            <mesh>
              <scale>1 1 1</scale>
              <uri>/home/hrisim/tiago_ws/src/pmb2_robot/pmb2_description/meshes/sensors/srf05.stl</uri>
            </mesh>
          </geometry>
          <material>
            <script>
              <name>Gazebo/DarkGrey</name>
              <uri>file://media/materials/scripts/gazebo.material</uri>
            </script>
          </material>
        </visual>
        <visual name='base_footprint_fixed_joint_lump__torso_fixed_column_link_visual_7'>
          <pose>-0.062 0 0.5685 0 -0 0</pose>
          <geometry>
            <box>
              <size>0.18 0.2 0.55</size>
            </box>
          </geometry>
          <material>
            <script>
              <name>Gazebo/DarkGrey</name>
              <uri>file://media/materials/scripts/gazebo.material</uri>
            </script>
          </material>
        </visual>
        <visual name='base_footprint_fixed_joint_lump__torso_fixed_link_visual_8'>
          <pose>-0.062 0 0.2915 0 -0 0</pose>
          <geometry>
            <mesh>
              <scale>1 1 1</scale>
              <uri>/home/hrisim/tiago_ws/src/tiago_robot/tiago_description/meshes/torso/torso_fix.stl</uri>
            </mesh>
          </geometry>
        </visual>
        <visual name='base_footprint_fixed_joint_lump__base_cover_link_visual_9'>
          <pose>0 0 0.13 0 -0 0</pose>
          <geometry>
            <mesh>
              <scale>1 1 1</scale>
              <uri>/home/hrisim/tiago_ws/src/pmb2_robot/pmb2_description/meshes/base/base_ring.stl</uri>
            </mesh>
          </geometry>
          <material>
            <script>
              <name>Gazebo/Orange</name>
              <uri>file://media/materials/scripts/gazebo.material</uri>
            </script>
          </material>
        </visual>
        <sensor name='imu_sensor' type='imu'>
          <always_on>1</always_on>
          <update_rate>1000</update_rate>
          <imu>
            <noise>
              <type>gaussian</type>
              <rate>
                <mean>0.0</mean>
                <stddev>2e-4</stddev>
                <bias_mean>0.0000075</bias_mean>
                <bias_stddev>0.0000008</bias_stddev>
              </rate>
              <accel>
                <mean>0.0</mean>
                <stddev>1.7e-2</stddev>
                <bias_mean>0.1</bias_mean>
                <bias_stddev>0.001</bias_stddev>
              </accel>
            </noise>
          </imu>
          <pose>0.10171 0 0.21132 0 0 -1.5708</pose>
        </sensor>
        <sensor name='base_imu_sensor' type='imu'>
          <always_on>1</always_on>
          <update_rate>100</update_rate>
          <imu>
            <noise>
              <type>gaussian</type>
              <rate>
                <mean>0.0</mean>
                <stddev>2e-4</stddev>
                <bias_mean>0.0000075</bias_mean>
                <bias_stddev>0.0000008</bias_stddev>
              </rate>
              <accel>
                <mean>0.0</mean>
                <stddev>1.7e-2</stddev>
                <bias_mean>0.1</bias_mean>
                <bias_stddev>0.001</bias_stddev>
              </accel>
            </noise>
          </imu>
          <pose>0.10171 0 0.21132 0 0 -1.5708</pose>
        </sensor>
        <sensor name='base_laser' type='gpu_ray'>
          <update_rate>10</update_rate>
          <visualize>1</visualize>
          <ray>
            <scan>
              <horizontal>
                <samples>666</samples>
                <resolution>1</resolution>
                <min_angle>-1.91986</min_angle>
                <max_angle>1.91986</max_angle>
              </horizontal>
              <vertical>
                <samples>1</samples>
                <min_angle>0</min_angle>
                <max_angle>0</max_angle>
              </vertical>
            </scan>
            <range>
              <min>0.05</min>
              <max>25</max>
              <resolution>0.001</resolution>
            </range>
          </ray>
          <plugin name='gazebo_ros_sick_laser' filename='libgazebo_ros_gpu_laser.so'>
            <gaussianNoise>0.06</gaussianNoise>
            <alwaysOn>1</alwaysOn>
            <updateRate>10</updateRate>
            <topicName>scan_raw</topicName>
            <frameName>base_laser_link</frameName>
            <robotNamespace>/</robotNamespace>
          </plugin>
          <pose>0.202 0 0.0945 0 -0 0</pose>
        </sensor>
        <sensor name='base_sonar_01' type='ray'>
          <update_rate>5</update_rate>
          <visualize>0</visualize>
          <ray>
            <scan>
              <horizontal>
                <samples>5</samples>
                <resolution>1</resolution>
                <min_angle>-0.25</min_angle>
                <max_angle>0.25</max_angle>
              </horizontal>
              <vertical>
                <samples>5</samples>
                <resolution>1</resolution>
                <min_angle>-0.25</min_angle>
                <max_angle>0.25</max_angle>
              </vertical>
            </scan>
            <range>
              <min>0.02</min>
              <max>1</max>
              <resolution>0.01</resolution>
            </range>
          </ray>
          <plugin name='gazebo_ros_range' filename='libgazebo_ros_range.so'>
            <gaussianNoise>0.005</gaussianNoise>
            <alwaysOn>1</alwaysOn>
            <updateRate>5</updateRate>
            <topicName>sonar_base</topicName>
            <frameName>base_sonar_01_link</frameName>
            <minRange>0.02</minRange>
            <maxRange>1.0</maxRange>
            <fov>0.5</fov>
            <radiation>ultrasound</radiation>
            <robotNamespace>/</robotNamespace>
          </plugin>
          <pose>-0.183 -0.183 0.2715 0 0 -2.35619</pose>
        </sensor>
        <sensor name='base_sonar_02' type='ray'>
          <update_rate>5</update_rate>
          <visualize>0</visualize>
          <ray>
            <scan>
              <horizontal>
                <samples>5</samples>
                <resolution>1</resolution>
                <min_angle>-0.25</min_angle>
                <max_angle>0.25</max_angle>
              </horizontal>
              <vertical>
                <samples>5</samples>
                <resolution>1</resolution>
                <min_angle>-0.25</min_angle>
                <max_angle>0.25</max_angle>
              </vertical>
            </scan>
            <range>
              <min>0.02</min>
              <max>1</max>
              <resolution>0.01</resolution>
            </range>
          </ray>
          <plugin name='gazebo_ros_range' filename='libgazebo_ros_range.so'>
            <gaussianNoise>0.005</gaussianNoise>
            <alwaysOn>1</alwaysOn>
            <updateRate>5</updateRate>
            <topicName>sonar_base</topicName>
            <frameName>base_sonar_02_link</frameName>
            <minRange>0.02</minRange>
            <maxRange>1.0</maxRange>
            <fov>0.5</fov>
            <radiation>ultrasound</radiation>
            <robotNamespace>/</robotNamespace>
          </plugin>
          <pose>-0.259 0 0.2715 0 -0 3.14159</pose>
        </sensor>
        <sensor name='base_sonar_03' type='ray'>
          <update_rate>5</update_rate>
          <visualize>0</visualize>
          <ray>
            <scan>
              <horizontal>
                <samples>5</samples>
                <resolution>1</resolution>
                <min_angle>-0.25</min_angle>
                <max_angle>0.25</max_angle>
              </horizontal>
              <vertical>
                <samples>5</samples>
                <resolution>1</resolution>
                <min_angle>-0.25</min_angle>
                <max_angle>0.25</max_angle>
              </vertical>
            </scan>
            <range>
              <min>0.02</min>
              <max>1</max>
              <resolution>0.01</resolution>
            </range>
          </ray>
          <plugin name='gazebo_ros_range' filename='libgazebo_ros_range.so'>
            <gaussianNoise>0.005</gaussianNoise>
            <alwaysOn>1</alwaysOn>
            <updateRate>5</updateRate>
            <topicName>sonar_base</topicName>
            <frameName>base_sonar_03_link</frameName>
            <minRange>0.02</minRange>
            <maxRange>1.0</maxRange>
            <fov>0.5</fov>
            <radiation>ultrasound</radiation>
            <robotNamespace>/</robotNamespace>
          </plugin>
          <pose>-0.183 0.183 0.2715 0 -0 2.35619</pose>
        </sensor>
        <self_collide>0</self_collide>
        <enable_wind>0</enable_wind>
        <kinematic>0</kinematic>
      </link>
      <joint name='caster_back_left_1_joint' type='revolute'>
        <pose relative_to='base_footprint'>-0.1735 0.102 0.065 0 -0 0</pose>
        <parent>base_footprint</parent>
        <child>caster_back_left_1_link</child>
        <axis>
          <xyz>0 0 1</xyz>
          <limit>
            <lower>-1e+16</lower>
            <upper>1e+16</upper>
          </limit>
          <dynamics>
            <damping>0.005</damping>
            <friction>0</friction>
            <spring_reference>0</spring_reference>
            <spring_stiffness>0</spring_stiffness>
          </dynamics>
        </axis>
      </joint>
      <link name='caster_back_left_1_link'>
        <pose relative_to='caster_back_left_1_joint'>0 0 0 0 -0 0</pose>
        <inertial>
          <pose>-0.006346 5.3e-05 -0.020375 0 -0 0</pose>
          <mass>0.0514476</mass>
          <inertia>
            <ixx>1.513e-05</ixx>
            <ixy>-3e-08</ixy>
            <ixz>2.67e-06</ixz>
            <iyy>1.309e-05</iyy>
            <iyz>-5e-08</iyz>
            <izz>1.198e-05</izz>
          </inertia>
        </inertial>
        <visual name='caster_back_left_1_link_visual'>
          <pose>0 0 0 0 -0 0</pose>
          <geometry>
            <mesh>
              <scale>1 1 1</scale>
              <uri>/home/hrisim/tiago_ws/src/pmb2_robot/pmb2_description/meshes/wheels/caster_1.stl</uri>
            </mesh>
          </geometry>
          <material>
            <script>
              <name>Gazebo/DarkGrey</name>
              <uri>file://media/materials/scripts/gazebo.material</uri>
            </script>
          </material>
        </visual>
        <self_collide>0</self_collide>
        <enable_wind>0</enable_wind>
        <kinematic>0</kinematic>
      </link>
      <joint name='caster_back_left_2_joint' type='revolute'>
        <pose relative_to='caster_back_left_1_link'>-0.016 0 -0.04 -1.5708 0 0</pose>
        <parent>caster_back_left_1_link</parent>
        <child>caster_back_left_2_link</child>
        <axis>
          <xyz>0 0 1</xyz>
          <limit>
            <lower>-1e+16</lower>
            <upper>1e+16</upper>
          </limit>
          <dynamics>
            <spring_reference>0</spring_reference>
            <spring_stiffness>0</spring_stiffness>
          </dynamics>
        </axis>
      </joint>
      <link name='caster_back_left_2_link'>
        <pose relative_to='caster_back_left_2_joint'>0 0 0 0 -0 0</pose>
        <inertial>
          <pose>0 0 0 0 -0 0</pose>
          <mass>0.0885578</mass>
          <inertia>
            <ixx>1.075e-05</ixx>
            <ixy>0</ixy>
            <ixz>0</ixz>
            <iyy>1.541e-05</iyy>
            <iyz>0</iyz>
            <izz>1.075e-05</izz>
          </inertia>
        </inertial>
        <collision name='caster_back_left_2_link_collision'>
          <pose>0 0 0 0 -0 0</pose>
          <geometry>
            <sphere>
              <radius>0.025</radius>
            </sphere>
          </geometry>
          <surface>
            <contact>
              <ode>
                <kp>1e+07</kp>
                <kd>10</kd>
                <max_vel>10</max_vel>
                <min_depth>0.0005</min_depth>
              </ode>
            </contact>
            <friction>
              <ode>
                <mu>0.1</mu>
                <mu2>0.1</mu2>
              </ode>
              <torsional>
                <ode/>
              </torsional>
            </friction>
            <bounce/>
          </surface>
          <max_contacts>10</max_contacts>
        </collision>
        <visual name='caster_back_left_2_link_visual'>
          <pose>0 0 0 0 -0 0</pose>
          <geometry>
            <mesh>
              <scale>1 1 1</scale>
              <uri>/home/hrisim/tiago_ws/src/pmb2_robot/pmb2_description/meshes/wheels/caster_2.stl</uri>
            </mesh>
          </geometry>
          <material>
            <script>
              <name>Gazebo/DarkGrey</name>
              <uri>file://media/materials/scripts/gazebo.material</uri>
            </script>
          </material>
        </visual>
        <self_collide>0</self_collide>
        <enable_wind>0</enable_wind>
        <kinematic>0</kinematic>
      </link>
      <joint name='caster_back_right_1_joint' type='revolute'>
        <pose relative_to='base_footprint'>-0.1735 -0.102 0.065 0 -0 0</pose>
        <parent>base_footprint</parent>
        <child>caster_back_right_1_link</child>
        <axis>
          <xyz>0 0 1</xyz>
          <limit>
            <lower>-1e+16</lower>
            <upper>1e+16</upper>
          </limit>
          <dynamics>
            <damping>0.005</damping>
            <friction>0</friction>
            <spring_reference>0</spring_reference>
            <spring_stiffness>0</spring_stiffness>
          </dynamics>
        </axis>
      </joint>
      <link name='caster_back_right_1_link'>
        <pose relative_to='caster_back_right_1_joint'>0 0 0 0 -0 0</pose>
        <inertial>
          <pose>-0.006346 5.3e-05 -0.020375 0 -0 0</pose>
          <mass>0.0514476</mass>
          <inertia>
            <ixx>1.513e-05</ixx>
            <ixy>-3e-08</ixy>
            <ixz>2.67e-06</ixz>
            <iyy>1.309e-05</iyy>
            <iyz>-5e-08</iyz>
            <izz>1.198e-05</izz>
          </inertia>
        </inertial>
        <visual name='caster_back_right_1_link_visual'>
          <pose>0 0 0 0 -0 0</pose>
          <geometry>
            <mesh>
              <scale>1 1 1</scale>
              <uri>/home/hrisim/tiago_ws/src/pmb2_robot/pmb2_description/meshes/wheels/caster_1.stl</uri>
            </mesh>
          </geometry>
          <material>
            <script>
              <name>Gazebo/DarkGrey</name>
              <uri>file://media/materials/scripts/gazebo.material</uri>
            </script>
          </material>
        </visual>
        <self_collide>0</self_collide>
        <enable_wind>0</enable_wind>
        <kinematic>0</kinematic>
      </link>
      <joint name='caster_back_right_2_joint' type='revolute'>
        <pose relative_to='caster_back_right_1_link'>-0.016 0 -0.04 -1.5708 0 0</pose>
        <parent>caster_back_right_1_link</parent>
        <child>caster_back_right_2_link</child>
        <axis>
          <xyz>0 0 1</xyz>
          <limit>
            <lower>-1e+16</lower>
            <upper>1e+16</upper>
          </limit>
          <dynamics>
            <spring_reference>0</spring_reference>
            <spring_stiffness>0</spring_stiffness>
          </dynamics>
        </axis>
      </joint>
      <link name='caster_back_right_2_link'>
        <pose relative_to='caster_back_right_2_joint'>0 0 0 0 -0 0</pose>
        <inertial>
          <pose>0 0 0 0 -0 0</pose>
          <mass>0.0885578</mass>
          <inertia>
            <ixx>1.075e-05</ixx>
            <ixy>0</ixy>
            <ixz>0</ixz>
            <iyy>1.541e-05</iyy>
            <iyz>0</iyz>
            <izz>1.075e-05</izz>
          </inertia>
        </inertial>
        <collision name='caster_back_right_2_link_collision'>
          <pose>0 0 0 0 -0 0</pose>
          <geometry>
            <sphere>
              <radius>0.025</radius>
            </sphere>
          </geometry>
          <surface>
            <contact>
              <ode>
                <kp>1e+07</kp>
                <kd>10</kd>
                <max_vel>10</max_vel>
                <min_depth>0.0005</min_depth>
              </ode>
            </contact>
            <friction>
              <ode>
                <mu>0.1</mu>
                <mu2>0.1</mu2>
              </ode>
              <torsional>
                <ode/>
              </torsional>
            </friction>
            <bounce/>
          </surface>
          <max_contacts>10</max_contacts>
        </collision>
        <visual name='caster_back_right_2_link_visual'>
          <pose>0 0 0 0 -0 0</pose>
          <geometry>
            <mesh>
              <scale>1 1 1</scale>
              <uri>/home/hrisim/tiago_ws/src/pmb2_robot/pmb2_description/meshes/wheels/caster_2.stl</uri>
            </mesh>
          </geometry>
          <material>
            <script>
              <name>Gazebo/DarkGrey</name>
              <uri>file://media/materials/scripts/gazebo.material</uri>
            </script>
          </material>
        </visual>
        <self_collide>0</self_collide>
        <enable_wind>0</enable_wind>
        <kinematic>0</kinematic>
      </link>
      <joint name='caster_front_left_1_joint' type='revolute'>
        <pose relative_to='base_footprint'>0.1695 0.102 0.065 0 -0 0</pose>
        <parent>base_footprint</parent>
        <child>caster_front_left_1_link</child>
        <axis>
          <xyz>0 0 1</xyz>
          <limit>
            <lower>-1e+16</lower>
            <upper>1e+16</upper>
          </limit>
          <dynamics>
            <damping>0.005</damping>
            <friction>0</friction>
            <spring_reference>0</spring_reference>
            <spring_stiffness>0</spring_stiffness>
          </dynamics>
        </axis>
      </joint>
      <link name='caster_front_left_1_link'>
        <pose relative_to='caster_front_left_1_joint'>0 0 0 0 -0 0</pose>
        <inertial>
          <pose>-0.006346 5.3e-05 -0.020375 0 -0 0</pose>
          <mass>0.0514476</mass>
          <inertia>
            <ixx>1.513e-05</ixx>
            <ixy>-3e-08</ixy>
            <ixz>2.67e-06</ixz>
            <iyy>1.309e-05</iyy>
            <iyz>-5e-08</iyz>
            <izz>1.198e-05</izz>
          </inertia>
        </inertial>
        <visual name='caster_front_left_1_link_visual'>
          <pose>0 0 0 0 -0 0</pose>
          <geometry>
            <mesh>
              <scale>1 1 1</scale>
              <uri>/home/hrisim/tiago_ws/src/pmb2_robot/pmb2_description/meshes/wheels/caster_1.stl</uri>
            </mesh>
          </geometry>
          <material>
            <script>
              <name>Gazebo/DarkGrey</name>
              <uri>file://media/materials/scripts/gazebo.material</uri>
            </script>
          </material>
        </visual>
        <self_collide>0</self_collide>
        <enable_wind>0</enable_wind>
        <kinematic>0</kinematic>
      </link>
      <joint name='caster_front_left_2_joint' type='revolute'>
        <pose relative_to='caster_front_left_1_link'>-0.016 0 -0.04 -1.5708 0 0</pose>
        <parent>caster_front_left_1_link</parent>
        <child>caster_front_left_2_link</child>
        <axis>
          <xyz>0 0 1</xyz>
          <limit>
            <lower>-1e+16</lower>
            <upper>1e+16</upper>
          </limit>
          <dynamics>
            <spring_reference>0</spring_reference>
            <spring_stiffness>0</spring_stiffness>
          </dynamics>
        </axis>
      </joint>
      <link name='caster_front_left_2_link'>
        <pose relative_to='caster_front_left_2_joint'>0 0 0 0 -0 0</pose>
        <inertial>
          <pose>0 0 0 0 -0 0</pose>
          <mass>0.0885578</mass>
          <inertia>
            <ixx>1.075e-05</ixx>
            <ixy>0</ixy>
            <ixz>0</ixz>
            <iyy>1.541e-05</iyy>
            <iyz>0</iyz>
            <izz>1.075e-05</izz>
          </inertia>
        </inertial>
        <collision name='caster_front_left_2_link_collision'>
          <pose>0 0 0 0 -0 0</pose>
          <geometry>
            <sphere>
              <radius>0.025</radius>
            </sphere>
          </geometry>
          <surface>
            <contact>
              <ode>
                <kp>1e+07</kp>
                <kd>10</kd>
                <max_vel>10</max_vel>
                <min_depth>0.0005</min_depth>
              </ode>
            </contact>
            <friction>
              <ode>
                <mu>0.1</mu>
                <mu2>0.1</mu2>
              </ode>
              <torsional>
                <ode/>
              </torsional>
            </friction>
            <bounce/>
          </surface>
          <max_contacts>10</max_contacts>
        </collision>
        <visual name='caster_front_left_2_link_visual'>
          <pose>0 0 0 0 -0 0</pose>
          <geometry>
            <mesh>
              <scale>1 1 1</scale>
              <uri>/home/hrisim/tiago_ws/src/pmb2_robot/pmb2_description/meshes/wheels/caster_2.stl</uri>
            </mesh>
          </geometry>
          <material>
            <script>
              <name>Gazebo/DarkGrey</name>
              <uri>file://media/materials/scripts/gazebo.material</uri>
            </script>
          </material>
        </visual>
        <self_collide>0</self_collide>
        <enable_wind>0</enable_wind>
        <kinematic>0</kinematic>
      </link>
      <joint name='caster_front_right_1_joint' type='revolute'>
        <pose relative_to='base_footprint'>0.1695 -0.102 0.065 0 -0 0</pose>
        <parent>base_footprint</parent>
        <child>caster_front_right_1_link</child>
        <axis>
          <xyz>0 0 1</xyz>
          <limit>
            <lower>-1e+16</lower>
            <upper>1e+16</upper>
          </limit>
          <dynamics>
            <damping>0.005</damping>
            <friction>0</friction>
            <spring_reference>0</spring_reference>
            <spring_stiffness>0</spring_stiffness>
          </dynamics>
        </axis>
      </joint>
      <link name='caster_front_right_1_link'>
        <pose relative_to='caster_front_right_1_joint'>0 0 0 0 -0 0</pose>
        <inertial>
          <pose>-0.006346 5.3e-05 -0.020375 0 -0 0</pose>
          <mass>0.0514476</mass>
          <inertia>
            <ixx>1.513e-05</ixx>
            <ixy>-3e-08</ixy>
            <ixz>2.67e-06</ixz>
            <iyy>1.309e-05</iyy>
            <iyz>-5e-08</iyz>
            <izz>1.198e-05</izz>
          </inertia>
        </inertial>
        <visual name='caster_front_right_1_link_visual'>
          <pose>0 0 0 0 -0 0</pose>
          <geometry>
            <mesh>
              <scale>1 1 1</scale>
              <uri>/home/hrisim/tiago_ws/src/pmb2_robot/pmb2_description/meshes/wheels/caster_1.stl</uri>
            </mesh>
          </geometry>
          <material>
            <script>
              <name>Gazebo/DarkGrey</name>
              <uri>file://media/materials/scripts/gazebo.material</uri>
            </script>
          </material>
        </visual>
        <self_collide>0</self_collide>
        <enable_wind>0</enable_wind>
        <kinematic>0</kinematic>
      </link>
      <joint name='caster_front_right_2_joint' type='revolute'>
        <pose relative_to='caster_front_right_1_link'>-0.016 0 -0.04 -1.5708 0 0</pose>
        <parent>caster_front_right_1_link</parent>
        <child>caster_front_right_2_link</child>
        <axis>
          <xyz>0 0 1</xyz>
          <limit>
            <lower>-1e+16</lower>
            <upper>1e+16</upper>
          </limit>
          <dynamics>
            <spring_reference>0</spring_reference>
            <spring_stiffness>0</spring_stiffness>
          </dynamics>
        </axis>
      </joint>
      <link name='caster_front_right_2_link'>
        <pose relative_to='caster_front_right_2_joint'>0 0 0 0 -0 0</pose>
        <inertial>
          <pose>0 0 0 0 -0 0</pose>
          <mass>0.0885578</mass>
          <inertia>
            <ixx>1.075e-05</ixx>
            <ixy>0</ixy>
            <ixz>0</ixz>
            <iyy>1.541e-05</iyy>
            <iyz>0</iyz>
            <izz>1.075e-05</izz>
          </inertia>
        </inertial>
        <collision name='caster_front_right_2_link_collision'>
          <pose>0 0 0 0 -0 0</pose>
          <geometry>
            <sphere>
              <radius>0.025</radius>
            </sphere>
          </geometry>
          <surface>
            <contact>
              <ode>
                <kp>1e+07</kp>
                <kd>10</kd>
                <max_vel>10</max_vel>
                <min_depth>0.0005</min_depth>
              </ode>
            </contact>
            <friction>
              <ode>
                <mu>0.1</mu>
                <mu2>0.1</mu2>
              </ode>
              <torsional>
                <ode/>
              </torsional>
            </friction>
            <bounce/>
          </surface>
          <max_contacts>10</max_contacts>
        </collision>
        <visual name='caster_front_right_2_link_visual'>
          <pose>0 0 0 0 -0 0</pose>
          <geometry>
            <mesh>
              <scale>1 1 1</scale>
              <uri>/home/hrisim/tiago_ws/src/pmb2_robot/pmb2_description/meshes/wheels/caster_2.stl</uri>
            </mesh>
          </geometry>
          <material>
            <script>
              <name>Gazebo/DarkGrey</name>
              <uri>file://media/materials/scripts/gazebo.material</uri>
            </script>
          </material>
        </visual>
        <self_collide>0</self_collide>
        <enable_wind>0</enable_wind>
        <kinematic>0</kinematic>
      </link>
      <joint name='suspension_left_joint' type='prismatic'>
        <pose relative_to='base_footprint'>0 0 0.0985 0 -0 0</pose>
        <parent>base_footprint</parent>
        <child>suspension_left_link</child>
        <axis>
          <xyz>0 0 1</xyz>
          <limit>
            <lower>-0.005</lower>
            <upper>0.005</upper>
            <effort>100</effort>
            <velocity>1</velocity>
          </limit>
          <dynamics>
            <damping>100</damping>
            <friction>0</friction>
            <spring_reference>0</spring_reference>
            <spring_stiffness>0</spring_stiffness>
          </dynamics>
        </axis>
      </joint>
      <link name='suspension_left_link'>
        <pose relative_to='suspension_left_joint'>0 0 0 0 -0 0</pose>
        <inertial>
          <pose>0 0 -0.02 0 -0 0</pose>
          <mass>10</mass>
          <inertia>
            <ixx>1</ixx>
            <ixy>0</ixy>
            <ixz>0</ixz>
            <iyy>1</iyy>
            <iyz>0</iyz>
            <izz>1</izz>
          </inertia>
        </inertial>
        <self_collide>0</self_collide>
        <enable_wind>0</enable_wind>
        <kinematic>0</kinematic>
      </link>
      <joint name='wheel_left_joint' type='revolute'>
        <pose relative_to='suspension_left_link'>0 0.2022 0 -1.5708 0 0</pose>
        <parent>suspension_left_link</parent>
        <child>wheel_left_link</child>
        <axis>
          <xyz>0 0 1</xyz>
          <limit>
            <effort>6</effort>
            <velocity>10.1523</velocity>
            <lower>-1e+16</lower>
            <upper>1e+16</upper>
          </limit>
          <dynamics>
            <spring_reference>0</spring_reference>
            <spring_stiffness>0</spring_stiffness>
          </dynamics>
        </axis>
      </joint>
      <link name='wheel_left_link'>
        <pose relative_to='wheel_left_joint'>0 0 0 0 -0 0</pose>
        <inertial>
          <pose>0 0 0.00207 0 -0 0</pose>
          <mass>1.82362</mass>
          <inertia>
            <ixx>0.00499743</ixx>
            <ixy>-4.464e-08</ixy>
            <ixz>-2.245e-08</ixz>
            <iyy>0.00499742</iyy>
            <iyz>1.64e-09</iyz>
            <izz>0.0083924</izz>
          </inertia>
        </inertial>
        <collision name='wheel_left_link_collision'>
          <pose>0 0 0 0 -0 0</pose>
          <geometry>
            <cylinder>
              <length>0.02</length>
              <radius>0.0985</radius>
            </cylinder>
          </geometry>
          <surface>
            <contact>
              <ode>
                <kp>1e+06</kp>
                <kd>100</kd>
                <max_vel>1</max_vel>
                <min_depth>0.002</min_depth>
              </ode>
            </contact>
            <friction>
              <ode>
                <mu>1e+14</mu>
                <mu2>1e+14</mu2>
              </ode>
              <torsional>
                <ode/>
              </torsional>
            </friction>
            <bounce/>
          </surface>
          <max_contacts>10</max_contacts>
        </collision>
        <visual name='wheel_left_link_visual'>
          <pose>0 0 0 -3.14159 0 0</pose>
          <geometry>
            <mesh>
              <scale>1 1 1</scale>
              <uri>/home/hrisim/tiago_ws/src/pmb2_robot/pmb2_description/meshes/wheels/wheel.stl</uri>
            </mesh>
          </geometry>
          <material>
            <script>
              <name>Gazebo/DarkGrey</name>
              <uri>file://media/materials/scripts/gazebo.material</uri>
            </script>
          </material>
        </visual>
        <self_collide>0</self_collide>
        <enable_wind>0</enable_wind>
        <kinematic>0</kinematic>
      </link>
      <joint name='suspension_right_joint' type='prismatic'>
        <pose relative_to='base_footprint'>0 0 0.0985 0 -0 0</pose>
        <parent>base_footprint</parent>
        <child>suspension_right_link</child>
        <axis>
          <xyz>0 0 1</xyz>
          <limit>
            <lower>-0.005</lower>
            <upper>0.005</upper>
            <effort>100</effort>
            <velocity>1</velocity>
          </limit>
          <dynamics>
            <damping>100</damping>
            <friction>0</friction>
            <spring_reference>0</spring_reference>
            <spring_stiffness>0</spring_stiffness>
          </dynamics>
        </axis>
      </joint>
      <link name='suspension_right_link'>
        <pose relative_to='suspension_right_joint'>0 0 0 0 -0 0</pose>
        <inertial>
          <pose>0 0 -0.02 0 -0 0</pose>
          <mass>10</mass>
          <inertia>
            <ixx>1</ixx>
            <ixy>0</ixy>
            <ixz>0</ixz>
            <iyy>1</iyy>
            <iyz>0</iyz>
            <izz>1</izz>
          </inertia>
        </inertial>
        <self_collide>0</self_collide>
        <enable_wind>0</enable_wind>
        <kinematic>0</kinematic>
      </link>
      <joint name='wheel_right_joint' type='revolute'>
        <pose relative_to='suspension_right_link'>0 -0.2022 0 -1.5708 0 0</pose>
        <parent>suspension_right_link</parent>
        <child>wheel_right_link</child>
        <axis>
          <xyz>0 0 1</xyz>
          <limit>
            <effort>6</effort>
            <velocity>10.1523</velocity>
            <lower>-1e+16</lower>
            <upper>1e+16</upper>
          </limit>
          <dynamics>
            <spring_reference>0</spring_reference>
            <spring_stiffness>0</spring_stiffness>
          </dynamics>
        </axis>
      </joint>
      <link name='wheel_right_link'>
        <pose relative_to='wheel_right_joint'>0 0 0 0 -0 0</pose>
        <inertial>
          <pose>0 0 -0.00207 0 -0 0</pose>
          <mass>1.82362</mass>
          <inertia>
            <ixx>0.00499743</ixx>
            <ixy>4.464e-08</ixy>
            <ixz>-2.245e-08</ixz>
            <iyy>0.00499742</iyy>
            <iyz>-1.64e-09</iyz>
            <izz>0.0083924</izz>
          </inertia>
        </inertial>
        <collision name='wheel_right_link_collision'>
          <pose>0 0 0 0 -0 0</pose>
          <geometry>
            <cylinder>
              <length>0.02</length>
              <radius>0.0985</radius>
            </cylinder>
          </geometry>
          <surface>
            <contact>
              <ode>
                <kp>1e+06</kp>
                <kd>100</kd>
                <max_vel>1</max_vel>
                <min_depth>0.002</min_depth>
              </ode>
            </contact>
            <friction>
              <ode>
                <mu>1e+14</mu>
                <mu2>1e+14</mu2>
              </ode>
              <torsional>
                <ode/>
              </torsional>
            </friction>
            <bounce/>
          </surface>
          <max_contacts>10</max_contacts>
        </collision>
        <visual name='wheel_right_link_visual'>
          <pose>0 0 0 0 -0 0</pose>
          <geometry>
            <mesh>
              <scale>1 1 1</scale>
              <uri>/home/hrisim/tiago_ws/src/pmb2_robot/pmb2_description/meshes/wheels/wheel.stl</uri>
            </mesh>
          </geometry>
          <material>
            <script>
              <name>Gazebo/DarkGrey</name>
              <uri>file://media/materials/scripts/gazebo.material</uri>
            </script>
          </material>
        </visual>
        <self_collide>0</self_collide>
        <enable_wind>0</enable_wind>
        <kinematic>0</kinematic>
      </link>
      <joint name='torso_lift_joint' type='prismatic'>
        <pose relative_to='base_footprint'>-0.062 0 0.8885 0 -0 0</pose>
        <parent>base_footprint</parent>
        <child>torso_lift_link</child>
        <axis>
          <xyz>0 0 1</xyz>
          <limit>
            <lower>0</lower>
            <upper>0.35</upper>
            <effort>2000</effort>
            <velocity>0.07</velocity>
          </limit>
          <dynamics>
            <damping>1000</damping>
            <friction>0</friction>
            <spring_reference>0</spring_reference>
            <spring_stiffness>0</spring_stiffness>
          </dynamics>
        </axis>
      </joint>
      <link name='torso_lift_link'>
        <pose relative_to='torso_lift_joint'>0 0 0 0 -0 0</pose>
        <inertial>
          <pose>0.04361 -0.00116 -0.17334 0 -0 0</pose>
          <mass>6.93198</mass>
          <inertia>
            <ixx>0.24487</ixx>
            <ixy>-0.001456</ixy>
            <ixz>-0.009742</ixz>
            <iyy>0.249269</iyy>
            <iyz>0.008281</iyz>
            <izz>0.090395</izz>
          </inertia>
        </inertial>
        <collision name='torso_lift_link_collision'>
          <pose>0 0 0 0 -0 0</pose>
          <geometry>
            <mesh>
              <scale>1 1 1</scale>
              <uri>/home/hrisim/tiago_ws/src/tiago_robot/tiago_description/meshes/torso/torso_lift_collision_core.dae</uri>
            </mesh>
          </geometry>
          <max_contacts>10</max_contacts>
          <surface>
            <contact>
              <ode/>
            </contact>
            <bounce/>
            <friction>
              <torsional>
                <ode/>
              </torsional>
              <ode/>
            </friction>
          </surface>
        </collision>
        <collision name='torso_lift_link_collision_1'>
          <pose>0 0 0 0 -0 0</pose>
          <geometry>
            <mesh>
              <scale>1 1 1</scale>
              <uri>/home/hrisim/tiago_ws/src/tiago_robot/tiago_description/meshes/torso/torso_lift_collision_shoulder.dae</uri>
            </mesh>
          </geometry>
          <max_contacts>10</max_contacts>
          <surface>
            <contact>
              <ode/>
            </contact>
            <bounce/>
            <friction>
              <torsional>
                <ode/>
              </torsional>
              <ode/>
            </friction>
          </surface>
        </collision>
        <collision name='torso_lift_link_collision_2'>
          <pose>0 0 0 0 -0 0</pose>
          <geometry>
            <mesh>
              <scale>1 1 1</scale>
              <uri>/home/hrisim/tiago_ws/src/tiago_robot/tiago_description/meshes/torso/torso_lift_collision_neck.dae</uri>
            </mesh>
          </geometry>
          <max_contacts>10</max_contacts>
          <surface>
            <contact>
              <ode/>
            </contact>
            <bounce/>
            <friction>
              <torsional>
                <ode/>
              </torsional>
              <ode/>
            </friction>
          </surface>
        </collision>
        <visual name='torso_lift_link_visual'>
          <pose>0 0 0 0 -0 0</pose>
          <geometry>
            <mesh>
              <scale>1 1 1</scale>
              <uri>/home/hrisim/tiago_ws/src/tiago_robot/tiago_description/meshes/torso/torso_lift_with_arm.stl</uri>
            </mesh>
          </geometry>
        </visual>
        <self_collide>0</self_collide>
        <enable_wind>0</enable_wind>
        <kinematic>0</kinematic>
      </link>
      <joint name='head_1_joint' type='revolute'>
        <pose relative_to='torso_lift_link'>0.182 0 0 0 -0 0</pose>
        <parent>torso_lift_link</parent>
        <child>head_1_link</child>
        <axis>
          <xyz>0 0 1</xyz>
          <limit>
            <lower>-1.309</lower>
            <upper>1.309</upper>
            <effort>5.197</effort>
            <velocity>3</velocity>
          </limit>
          <dynamics>
            <damping>0.5</damping>
            <friction>1</friction>
            <spring_reference>0</spring_reference>
            <spring_stiffness>0</spring_stiffness>
          </dynamics>
        </axis>
        <physics>
          <ode>
            <implicit_spring_damper>1</implicit_spring_damper>
            <cfm_damping>1</cfm_damping>
            <limit>
              <cfm>0</cfm>
              <erp>0.2</erp>
            </limit>
          </ode>
        </physics>
      </joint>
      <link name='head_1_link'>
        <pose relative_to='head_1_joint'>0 0 0 0 -0 0</pose>
        <inertial>
          <pose>-0.00508 0.00237 0.07229 0 -0 0</pose>
          <mass>0.6222</mass>
          <inertia>
            <ixx>0.001192</ixx>
            <ixy>-7e-06</ixy>
            <ixz>9.6e-05</ixz>
            <iyy>0.001402</iyy>
            <iyz>4e-06</iyz>
            <izz>0.000889</izz>
          </inertia>
        </inertial>
        <collision name='head_1_link_collision'>
          <pose>0 0 0 0 -0 0</pose>
          <geometry>
            <mesh>
              <scale>1 1 1</scale>
              <uri>/home/hrisim/tiago_ws/src/tiago_robot/tiago_description/meshes/head/head_1_collision.dae</uri>
            </mesh>
          </geometry>
          <surface>
            <contact>
              <ode/>
            </contact>
            <friction>
              <ode>
                <mu>0.9</mu>
                <mu2>0.9</mu2>
              </ode>
              <torsional>
                <ode/>
              </torsional>
            </friction>
            <bounce/>
          </surface>
          <max_contacts>10</max_contacts>
        </collision>
        <visual name='head_1_link_visual'>
          <pose>0 0 0 0 -0 0</pose>
          <geometry>
            <mesh>
              <scale>1 1 1</scale>
              <uri>/home/hrisim/tiago_ws/src/tiago_robot/tiago_description/meshes/head/head_1.stl</uri>
            </mesh>
          </geometry>
        </visual>
        <self_collide>0</self_collide>
        <enable_wind>0</enable_wind>
        <kinematic>0</kinematic>
      </link>
      <joint name='head_2_joint' type='revolute'>
        <pose relative_to='head_1_link'>0.005 0 0.098 1.5708 -0 0</pose>
        <parent>head_1_link</parent>
        <child>head_2_link</child>
        <axis>
          <xyz>0 0 1</xyz>
          <limit>
            <lower>-1.0472</lower>
            <upper>0.785398</upper>
            <effort>2.77</effort>
            <velocity>3</velocity>
          </limit>
          <dynamics>
            <damping>0.5</damping>
            <friction>1</friction>
            <spring_reference>0</spring_reference>
            <spring_stiffness>0</spring_stiffness>
          </dynamics>
        </axis>
      </joint>
      <link name='head_2_link'>
        <pose relative_to='head_2_joint'>0 0 0 0 -0 0</pose>
        <inertial>
          <pose>0.055827 0.060999 1.6e-05 0 -0 0</pose>
          <mass>0.88693</mass>
          <inertia>
            <ixx>0.00477062</ixx>
            <ixy>0.000560916</ixy>
            <ixz>1.19415e-05</ixz>
            <iyy>0.00513368</iyy>
            <iyz>9.32647e-06</iyz>
            <izz>0.00347598</izz>
          </inertia>
        </inertial>
        <collision name='head_2_link_collision'>
          <pose>0 0 0 0 -0 0</pose>
          <geometry>
            <mesh>
              <scale>1 1 1</scale>
              <uri>/home/hrisim/tiago_ws/src/tiago_robot/tiago_description/meshes/head/head_2_collision.dae</uri>
            </mesh>
          </geometry>
          <max_contacts>10</max_contacts>
          <surface>
            <contact>
              <ode/>
            </contact>
            <bounce/>
            <friction>
              <torsional>
                <ode/>
              </torsional>
              <ode/>
            </friction>
          </surface>
        </collision>
        <visual name='head_2_link_visual'>
          <pose>0 0 0 0 -0 0</pose>
          <geometry>
            <mesh>
              <scale>1 1 1</scale>
              <uri>/home/hrisim/tiago_ws/src/tiago_robot/tiago_description/meshes/head/head_2.stl</uri>
            </mesh>
          </geometry>
        </visual>
        <sensor name='xtion_frame_sensor' type='depth'>
          <always_on>1</always_on>
          <update_rate>30</update_rate>
          <camera>
            <horizontal_fov>1.09956</horizontal_fov>
            <image>
              <format>B8G8R8</format>
              <width>640</width>
              <height>480</height>
            </image>
            <clip>
              <near>0.3</near>
              <far>8</far>
            </clip>
          </camera>
          <plugin name='xtion_frame_controller' filename='libgazebo_ros_openni_kinect.so'>
            <alwaysOn>1</alwaysOn>
            <updateRate>30.0</updateRate>
            <cameraName>xtion</cameraName>
            <imageTopicName>rgb/image_raw</imageTopicName>
            <cameraInfoTopicName>rgb/camera_info</cameraInfoTopicName>
            <depthImageTopicName>depth_registered/image_raw</depthImageTopicName>
            <depthImageCameraInfoTopicName>depth_registered/camera_info</depthImageCameraInfoTopicName>
            <pointCloudTopicName>depth_registered/points</pointCloudTopicName>
            <frameName>xtion_rgb_optical_frame</frameName>
            <pointCloudCutoff>0.5</pointCloudCutoff>
            <pointCloudCutoffMax>8.0</pointCloudCutoffMax>
            <distortionK1>0.00000001</distortionK1>
            <distortionK2>0.00000001</distortionK2>
            <distortionK3>0.00000001</distortionK3>
            <distortionT1>0.00000001</distortionT1>
            <distortionT2>0.00000001</distortionT2>
            <robotNamespace>/</robotNamespace>
          </plugin>
          <pose>0.0908 0.08 -0.022 -1.5708 0 0</pose>
        </sensor>
        <self_collide>0</self_collide>
        <enable_wind>0</enable_wind>
        <kinematic>0</kinematic>
      </link>
      <plugin name='gazebo_ros_control' filename='libgazebo_ros_control.so'>
        <ns/>
        <robotSimType>pal_hardware_gazebo/PalHardwareGazebo</robotSimType>
        <robotNamespace/>
        <controlPeriod>0.001</controlPeriod>
      </plugin>
      <plugin name='gazebo_ros_p3d' filename='libgazebo_ros_p3d.so'>
        <bodyName>base_footprint</bodyName>
        <topicName>ground_truth_odom</topicName>
        <alwaysOn>1</alwaysOn>
        <updateRate>100.0</updateRate>
        <robotNamespace>/</robotNamespace>
      </plugin>
      <plugin name='gazebo_ros_odometry' filename='libgazebo_world_odometry.so'>
        <frameName>base_footprint</frameName>
        <topicName>floating_base_pose_simulated</topicName>
        <robotNamespace>/</robotNamespace>
      </plugin>
      <frame name='base_antenna_left_joint' attached_to='base_link'>
        <pose>-0.201 0.1062 0.195 0 -0 0</pose>
      </frame>
      <frame name='base_antenna_left_link' attached_to='base_antenna_left_joint'/>
      <frame name='base_antenna_right_joint' attached_to='base_link'>
        <pose>-0.201 -0.1062 0.195 0 -0 0</pose>
      </frame>
      <frame name='base_antenna_right_link' attached_to='base_antenna_right_joint'/>
      <frame name='base_imu_joint' attached_to='base_link'>
        <pose>0.10171 0 0.11282 0 0 -1.5708</pose>
      </frame>
      <frame name='base_imu_link' attached_to='base_imu_joint'/>
      <frame name='base_laser_joint' attached_to='base_link'>
        <pose>0.202 0 -0.004 0 -0 0</pose>
      </frame>
      <frame name='base_laser_link' attached_to='base_laser_joint'/>
      <frame name='base_mic_back_left_joint' attached_to='base_link'>
        <pose>-0.1082 -0.0599 0.195 0 -0 0</pose>
      </frame>
      <frame name='base_mic_back_left_link' attached_to='base_mic_back_left_joint'/>
      <frame name='base_mic_back_right_joint' attached_to='base_link'>
        <pose>-0.1082 -0.13789 0.195 0 -0 0</pose>
      </frame>
      <frame name='base_mic_back_right_link' attached_to='base_mic_back_right_joint'/>
      <frame name='base_mic_front_left_joint' attached_to='base_link'>
        <pose>0.23182 0.03902 0.195 0 -0 0</pose>
      </frame>
      <frame name='base_mic_front_left_link' attached_to='base_mic_front_left_joint'/>
      <frame name='base_mic_front_right_joint' attached_to='base_link'>
        <pose>0.23182 -0.03902 0.195 0 -0 0</pose>
      </frame>
      <frame name='base_mic_front_right_link' attached_to='base_mic_front_right_joint'/>
      <frame name='base_sonar_01_joint' attached_to='base_link'>
        <pose>-0.183 -0.183 0.173 0 -0 -2.35619</pose>
      </frame>
      <frame name='base_sonar_01_link' attached_to='base_sonar_01_joint'/>
      <frame name='base_sonar_02_joint' attached_to='base_link'>
        <pose>-0.259 0 0.173 0 -0 3.14159</pose>
      </frame>
      <frame name='base_sonar_02_link' attached_to='base_sonar_02_joint'/>
      <frame name='base_sonar_03_joint' attached_to='base_link'>
        <pose>-0.183 0.183 0.173 0 -0 2.35619</pose>
      </frame>
      <frame name='base_sonar_03_link' attached_to='base_sonar_03_joint'/>
      <frame name='torso_fixed_column_joint' attached_to='base_link'>
        <pose>-0.062 0 0.195 0 -0 0</pose>
      </frame>
      <frame name='torso_fixed_column_link' attached_to='torso_fixed_column_joint'/>
      <frame name='torso_fixed_joint' attached_to='base_link'>
        <pose>-0.062 0 0.193 0 -0 0</pose>
      </frame>
      <frame name='torso_fixed_link' attached_to='torso_fixed_joint'/>
      <frame name='xtion_optical_joint' attached_to='xtion_link'>
        <pose>0 0 0 -1.5708 -0 -1.5708</pose>
      </frame>
      <frame name='xtion_optical_frame' attached_to='xtion_optical_joint'/>
      <frame name='xtion_depth_optical_joint' attached_to='xtion_depth_frame'>
        <pose>0 0 0 -1.5708 -0 -1.5708</pose>
      </frame>
      <frame name='xtion_depth_optical_frame' attached_to='xtion_depth_optical_joint'/>
      <frame name='xtion_depth_joint' attached_to='xtion_rgb_frame'>
        <pose>0 0.025 0 0 -0 0</pose>
      </frame>
      <frame name='xtion_depth_frame' attached_to='xtion_depth_joint'/>
      <frame name='xtion_rgb_optical_joint' attached_to='xtion_rgb_frame'>
        <pose>0 0 0 -1.5708 -0 -1.5708</pose>
      </frame>
      <frame name='xtion_rgb_optical_frame' attached_to='xtion_rgb_optical_joint'/>
      <frame name='xtion_rgb_joint' attached_to='xtion_orbbec_aux_joint_frame'>
        <pose>0 0.022 0 0 -0 0</pose>
      </frame>
      <frame name='xtion_rgb_frame' attached_to='xtion_rgb_joint'/>
      <frame name='xtion_orbbec_aux_joint' attached_to='xtion_link'>
        <pose>0 0 0 0 -0 0</pose>
      </frame>
      <frame name='xtion_orbbec_aux_joint_frame' attached_to='xtion_orbbec_aux_joint'/>
      <frame name='xtion_joint' attached_to='head_2_link'>
        <pose>0.0908 0.08 0 -1.5708 0 0</pose>
      </frame>
      <frame name='xtion_link' attached_to='xtion_joint'/>
      <frame name='base_footprint_joint' attached_to='base_footprint'>
        <pose>0 0 0.0985 0 -0 0</pose>
      </frame>
      <frame name='base_link' attached_to='base_footprint_joint'/>
      <frame name='cover_joint' attached_to='base_footprint'>
        <pose>0 0 0.13 0 -0 0</pose>
      </frame>
      <frame name='base_cover_link' attached_to='cover_joint'/>
      <frame name='rgbd_laser_joint' attached_to='base_footprint'>
        <pose>-0.9 0 0 0 -0 0</pose>
      </frame>
      <frame name='rgbd_laser_link' attached_to='rgbd_laser_joint'/>
      <pose>-6 0 0 0 -0 0</pose>
    </model>
    <model name='0'>
      <link name='link'>
        <kinematic>1</kinematic>
        <inertial>
          <mass>20</mass>
          <inertia>
            <ixx>0</ixx>
            <ixy>0</ixy>
            <ixz>0</ixz>
            <iyy>0</iyy>
            <iyz>0</iyz>
            <izz>0</izz>
          </inertia>
          <pose>0 0 0 0 -0 0</pose>
        </inertial>
        <collision name='collision'>
          <pose>0 0 0 0 -0 1.5708</pose>
          <geometry>
            <mesh>
              <uri>model://citizen_extras_female_02/meshes/mesh.dae</uri>
            </mesh>
          </geometry>
          <max_contacts>10</max_contacts>
          <surface>
            <contact>
              <ode/>
            </contact>
            <bounce/>
            <friction>
              <torsional>
                <ode/>
              </torsional>
              <ode/>
            </friction>
          </surface>
        </collision>
        <visual name='visual'>
          <pose>0 0 0 0 -0 1.5708</pose>
          <geometry>
            <mesh>
              <uri>model://citizen_extras_female_02/meshes/mesh.dae</uri>
            </mesh>
          </geometry>
        </visual>
        <self_collide>0</self_collide>
        <enable_wind>0</enable_wind>
      </link>
      <pose>0.01498 -8.69597 0 0 -0 1.67977</pose>
    </model>
    <model name='1'>
      <link name='link'>
        <kinematic>1</kinematic>
        <inertial>
          <mass>20</mass>
          <inertia>
            <ixx>0</ixx>
            <ixy>0</ixy>
            <ixz>0</ixz>
            <iyy>0</iyy>
            <iyz>0</iyz>
            <izz>0</izz>
          </inertia>
          <pose>0 0 0 0 -0 0</pose>
        </inertial>
        <collision name='collision'>
          <pose>0 0 0 0 -0 1.5708</pose>
          <geometry>
            <mesh>
              <uri>model://citizen_extras_female_03/meshes/mesh.dae</uri>
            </mesh>
          </geometry>
          <max_contacts>10</max_contacts>
          <surface>
            <contact>
              <ode/>
            </contact>
            <bounce/>
            <friction>
              <torsional>
                <ode/>
              </torsional>
              <ode/>
            </friction>
          </surface>
        </collision>
        <visual name='visual'>
          <pose>0 0 0 0 -0 1.5708</pose>
          <geometry>
            <mesh>
              <uri>model://citizen_extras_female_03/meshes/mesh.dae</uri>
            </mesh>
          </geometry>
        </visual>
        <self_collide>0</self_collide>
        <enable_wind>0</enable_wind>
      </link>
      <pose>0.371641 -7.10369 0 0 0 -2.07402</pose>
    </model>
    <model name='2'>
      <link name='link'>
        <kinematic>1</kinematic>
        <inertial>
          <mass>20</mass>
          <inertia>
            <ixx>0</ixx>
            <ixy>0</ixy>
            <ixz>0</ixz>
            <iyy>0</iyy>
            <iyz>0</iyz>
            <izz>0</izz>
          </inertia>
          <pose>0 0 0 0 -0 0</pose>
        </inertial>
        <collision name='collision'>
          <pose>0 0 0 0 -0 1.5708</pose>
          <geometry>
            <mesh>
              <uri>model://citizen_extras_male_03/meshes/mesh.dae</uri>
            </mesh>
          </geometry>
          <max_contacts>10</max_contacts>
          <surface>
            <contact>
              <ode/>
            </contact>
            <bounce/>
            <friction>
              <torsional>
                <ode/>
              </torsional>
              <ode/>
            </friction>
          </surface>
        </collision>
        <visual name='visual'>
          <pose>0 0 0 0 -0 1.5708</pose>
          <geometry>
            <mesh>
              <uri>model://citizen_extras_male_03/meshes/mesh.dae</uri>
            </mesh>
          </geometry>
        </visual>
        <self_collide>0</self_collide>
        <enable_wind>0</enable_wind>
      </link>
      <pose>-0.218308 -5.28441 0 0 0 -1.37236</pose>
    </model>
    <model name='3'>
      <link name='link'>
        <kinematic>1</kinematic>
        <inertial>
          <mass>20</mass>
          <inertia>
            <ixx>0</ixx>
            <ixy>0</ixy>
            <ixz>0</ixz>
            <iyy>0</iyy>
            <iyz>0</iyz>
            <izz>0</izz>
          </inertia>
          <pose>0 0 0 0 -0 0</pose>
        </inertial>
        <collision name='collision'>
          <pose>0 0 0 0 -0 1.5708</pose>
          <geometry>
            <mesh>
              <uri>model://citizen_extras_female_03/meshes/mesh.dae</uri>
            </mesh>
          </geometry>
          <max_contacts>10</max_contacts>
          <surface>
            <contact>
              <ode/>
            </contact>
            <bounce/>
            <friction>
              <torsional>
                <ode/>
              </torsional>
              <ode/>
            </friction>
          </surface>
        </collision>
        <visual name='visual'>
          <pose>0 0 0 0 -0 1.5708</pose>
          <geometry>
            <mesh>
              <uri>model://citizen_extras_female_03/meshes/mesh.dae</uri>
            </mesh>
          </geometry>
        </visual>
        <self_collide>0</self_collide>
        <enable_wind>0</enable_wind>
      </link>
      <pose>0.5 -6 0 0 -0 0</pose>
    </model>
    <model name='4'>
      <link name='link'>
        <kinematic>1</kinematic>
        <inertial>
          <mass>20</mass>
          <inertia><ixx>0</ixx><ixy>0</ixy><ixz>0</ixz><iyy>0</iyy><iyz>0</iyz><izz>0</izz></inertia>
          <pose>0 0 0 0 -0 0</pose>
        </inertial>
        <collision name='collision'>
          <pose>0 0 0 0 -0 1.5708</pose>
          <geometry><mesh><uri>model://citizen_extras_female_02/meshes/mesh.dae</uri></mesh></geometry>
          <max_contacts>10</max_contacts>
          <surface><contact><ode/></contact><bounce/><friction><torsional><ode/></torsional><ode/></friction></surface>
        </collision>
        <visual name='visual'>
          <pose>0 0 0 0 -0 1.5708</pose>
          <geometry><mesh><uri>model://citizen_extras_female_02/meshes/mesh.dae</uri></mesh></geometry>
        </visual>
        <self_collide>0</self_collide>
        <enable_wind>0</enable_wind>
      </link>
      <pose>0.3 0.0 0 0 -0 0</pose>
    </model>
    <model name='5'>
      <link name='link'>
        <kinematic>1</kinematic>
        <inertial>
          <mass>20</mass>
          <inertia><ixx>0</ixx><ixy>0</ixy><ixz>0</ixz><iyy>0</iyy><iyz>0</iyz><izz>0</izz></inertia>
          <pose>0 0 0 0 -0 0</pose>
        </inertial>
        <collision name='collision'>
          <pose>0 0 0 0 -0 1.5708</pose>
          <geometry><mesh><uri>model://citizen_extras_female_03/meshes/mesh.dae</uri></mesh></geometry>
          <max_contacts>10</max_contacts>
          <surface><contact><ode/></contact><bounce/><friction><torsional><ode/></torsional><ode/></friction></surface>
        </collision>
        <visual name='visual'>
          <pose>0 0 0 0 -0 1.5708</pose>
          <geometry><mesh><uri>model://citizen_extras_female_03/meshes/mesh.dae</uri></mesh></geometry>
        </visual>
        <self_collide>0</self_collide>
        <enable_wind>0</enable_wind>
      </link>
      <pose>-0.3 0.1 0 0 -0 0</pose>
    </model>
    <model name='6'>
      <link name='link'>
        <kinematic>1</kinematic>
        <inertial>
          <mass>20</mass>
          <inertia><ixx>0</ixx><ixy>0</ixy><ixz>0</ixz><iyy>0</iyy><iyz>0</iyz><izz>0</izz></inertia>
          <pose>0 0 0 0 -0 0</pose>
        </inertial>
        <collision name='collision'>
          <pose>0 0 0 0 -0 1.5708</pose>
          <geometry><mesh><uri>model://citizen_extras_male_03/meshes/mesh.dae</uri></mesh></geometry>
          <max_contacts>10</max_contacts>
          <surface><contact><ode/></contact><bounce/><friction><torsional><ode/></torsional><ode/></friction></surface>
        </collision>
        <visual name='visual'>
          <pose>0 0 0 0 -0 1.5708</pose>
          <geometry><mesh><uri>model://citizen_extras_male_03/meshes/mesh.dae</uri></mesh></geometry>
        </visual>
        <self_collide>0</self_collide>
        <enable_wind>0</enable_wind>
      </link>
      <pose>0.1 -0.2 0 0 -0 0</pose>
    </model>
    <model name='7'>
      <link name='link'>
        <kinematic>1</kinematic>
        <inertial>
          <mass>20</mass>
          <inertia><ixx>0</ixx><ixy>0</ixy><ixz>0</ixz><iyy>0</iyy><iyz>0</iyz><izz>0</izz></inertia>
          <pose>0 0 0 0 -0 0</pose>
        </inertial>
        <collision name='collision'>
          <pose>0 0 0 0 -0 1.5708</pose>
          <geometry><mesh><uri>model://citizen_extras_female_02/meshes/mesh.dae</uri></mesh></geometry>
          <max_contacts>10</max_contacts>
          <surface><contact><ode/></contact><bounce/><friction><torsional><ode/></torsional><ode/></friction></surface>
        </collision>
        <visual name='visual'>
          <pose>0 0 0 0 -0 1.5708</pose>
          <geometry><mesh><uri>model://citizen_extras_female_02/meshes/mesh.dae</uri></mesh></geometry>
        </visual>
        <self_collide>0</self_collide>
        <enable_wind>0</enable_wind>
      </link>
      <pose>-0.1 0.2 0 0 -0 0</pose>
    </model>
    <model name='poster_0'>
      <link name='Wall_0'>
        <pose>-4.7604 -4.48691 0 0 -0 0</pose>
        <self_collide>0</self_collide>
        <enable_wind>0</enable_wind>
        <kinematic>0</kinematic>
        <visual name='Wall_0_Visual'>
          <pose>0 0 1.25 0 -0 0</pose>
          <geometry>
            <box>
              <size>1.65 0.3 2.5</size>
            </box>
          </geometry>
          <material>
            <ambient>0.1 0.1 0.1 1</ambient>
            <shader type='pixel'/>
            <script>
              <name>ModelPreview_1::Wall_0::Wall_0_Visual_MATERIAL_</name>
              <uri>__default__</uri>
            </script>
          </material>
          <meta>
            <layer>0</layer>
          </meta>
          <transparency>0</transparency>
          <cast_shadows>1</cast_shadows>
        </visual>
        <visual name='Poster_Face_Visual'>
          <pose>0 0.151 1.25 0 -0 0</pose>
          <geometry>
            <box>
              <size>1.65 0.001 2.5</size>
            </box>
          </geometry>
          <material>
            <script>
              <uri>model://poster/materials/scripts/poster.material</uri>
              <uri>model://poster/materials/textures/poster.png</uri>
              <name>Poster/Image</name>
            </script>
            <shader type='pixel'/>
          </material>
          <transparency>0</transparency>
          <cast_shadows>1</cast_shadows>
        </visual>
        <visual name='Poster_Back_Visual'>
          <pose>0 -0.151 1.25 0 -0 3.14159</pose>
          <geometry>
            <box>
              <size>1.65 0.001 2.5</size>
            </box>
          </geometry>
          <material>
            <script>
              <uri>model://poster/materials/scripts/poster.material</uri>
              <uri>model://poster/materials/textures/poster.png</uri>
              <name>Poster/Image</name>
            </script>
            <shader type='pixel'/>
          </material>
          <transparency>0</transparency>
          <cast_shadows>1</cast_shadows>
        </visual>
        <collision name='Wall_0_Collision'>
          <laser_retro>0</laser_retro>
          <max_contacts>10</max_contacts>
          <pose>0 0 1.25 0 -0 0</pose>
          <geometry>
            <box>
              <size>1.65 0.3 2.5</size>
            </box>
          </geometry>
          <surface>
            <friction>
              <ode>
                <mu>1</mu>
                <mu2>1</mu2>
                <fdir1>0 0 0</fdir1>
                <slip1>0</slip1>
                <slip2>0</slip2>
              </ode>
              <torsional>
                <coefficient>1</coefficient>
                <patch_radius>0</patch_radius>
                <surface_radius>0</surface_radius>
                <use_patch_radius>1</use_patch_radius>
                <ode>
                  <slip>0</slip>
                </ode>
              </torsional>
            </friction>
            <bounce>
              <restitution_coefficient>0</restitution_coefficient>
              <threshold>1e+06</threshold>
            </bounce>
            <contact>
              <collide_without_contact>0</collide_without_contact>
              <collide_without_contact_bitmask>1</collide_without_contact_bitmask>
              <collide_bitmask>1</collide_bitmask>
              <ode>
                <soft_cfm>0</soft_cfm>
                <soft_erp>0.2</soft_erp>
                <kp>1e+13</kp>
                <kd>1</kd>
                <max_vel>0.01</max_vel>
                <min_depth>0</min_depth>
              </ode>
              <bullet>
                <split_impulse>1</split_impulse>
                <split_impulse_penetration_threshold>-0.01</split_impulse_penetration_threshold>
                <soft_cfm>0</soft_cfm>
                <soft_erp>0.2</soft_erp>
                <kp>1e+13</kp>
                <kd>1</kd>
              </bullet>
            </contact>
          </surface>
        </collision>
      </link>
      <static>1</static>
      <allow_auto_disable>1</allow_auto_disable>
      <pose>3.89372 5.77585 0 0 -0 0</pose>
    </model>
    <model name='poster_1'>
      <link name='Wall_0'>
        <pose>-4.7604 -4.48691 0 0 -0 0</pose>
        <self_collide>0</self_collide>
        <enable_wind>0</enable_wind>
        <kinematic>0</kinematic>
        <visual name='Wall_0_Visual'>
          <pose>0 0 1.25 0 -0 0</pose>
          <geometry>
            <box>
              <size>1.65 0.3 2.5</size>
            </box>
          </geometry>
          <material>
            <ambient>0.1 0.1 0.1 1</ambient>
            <shader type='pixel'/>
            <script>
              <name>ModelPreview_1::Wall_0::Wall_0_Visual_MATERIAL_</name>
              <uri>__default__</uri>
            </script>
          </material>
          <meta>
            <layer>0</layer>
          </meta>
          <transparency>0</transparency>
          <cast_shadows>1</cast_shadows>
        </visual>
        <visual name='Poster_Face_Visual'>
          <pose>0 0.151 1.25 0 -0 0</pose>
          <geometry>
            <box>
              <size>1.65 0.001 2.5</size>
            </box>
          </geometry>
          <material>
            <script>
              <uri>model://poster/materials/scripts/poster.material</uri>
              <uri>model://poster/materials/textures/poster.png</uri>
              <name>Poster/Image</name>
            </script>
            <shader type='pixel'/>
          </material>
          <transparency>0</transparency>
          <cast_shadows>1</cast_shadows>
        </visual>
        <visual name='Poster_Back_Visual'>
          <pose>0 -0.151 1.25 0 -0 3.14159</pose>
          <geometry>
            <box>
              <size>1.65 0.001 2.5</size>
            </box>
          </geometry>
          <material>
            <script>
              <uri>model://poster/materials/scripts/poster.material</uri>
              <uri>model://poster/materials/textures/poster.png</uri>
              <name>Poster/Image</name>
            </script>
            <shader type='pixel'/>
          </material>
          <transparency>0</transparency>
          <cast_shadows>1</cast_shadows>
        </visual>
        <collision name='Wall_0_Collision'>
          <laser_retro>0</laser_retro>
          <max_contacts>10</max_contacts>
          <pose>0 0 1.25 0 -0 0</pose>
          <geometry>
            <box>
              <size>1.65 0.3 2.5</size>
            </box>
          </geometry>
          <surface>
            <friction>
              <ode>
                <mu>1</mu>
                <mu2>1</mu2>
                <fdir1>0 0 0</fdir1>
                <slip1>0</slip1>
                <slip2>0</slip2>
              </ode>
              <torsional>
                <coefficient>1</coefficient>
                <patch_radius>0</patch_radius>
                <surface_radius>0</surface_radius>
                <use_patch_radius>1</use_patch_radius>
                <ode>
                  <slip>0</slip>
                </ode>
              </torsional>
            </friction>
            <bounce>
              <restitution_coefficient>0</restitution_coefficient>
              <threshold>1e+06</threshold>
            </bounce>
            <contact>
              <collide_without_contact>0</collide_without_contact>
              <collide_without_contact_bitmask>1</collide_without_contact_bitmask>
              <collide_bitmask>1</collide_bitmask>
              <ode>
                <soft_cfm>0</soft_cfm>
                <soft_erp>0.2</soft_erp>
                <kp>1e+13</kp>
                <kd>1</kd>
                <max_vel>0.01</max_vel>
                <min_depth>0</min_depth>
              </ode>
              <bullet>
                <split_impulse>1</split_impulse>
                <split_impulse_penetration_threshold>-0.01</split_impulse_penetration_threshold>
                <soft_cfm>0</soft_cfm>
                <soft_erp>0.2</soft_erp>
                <kp>1e+13</kp>
                <kd>1</kd>
              </bullet>
            </contact>
          </surface>
        </collision>
      </link>
      <static>1</static>
      <allow_auto_disable>1</allow_auto_disable>
      <pose>5.53727 5.77499 0 0 -0 0</pose>
    </model>
    <gui fullscreen='0'>
      <camera name='user_camera'>
        <pose>-4.79793 -2.41639 16.7132 0 1.5698 -0.016</pose>
        <view_controller>orbit</view_controller>
        <projection_type>perspective</projection_type>
      </camera>
    </gui>
    <model name='ground_plane'>
      <static>1</static>
      <link name='link'>
        <collision name='collision'>
          <geometry>
            <plane>
              <normal>0 0 1</normal>
              <size>100 100</size>
            </plane>
          </geometry>
          <surface>
            <contact>
              <collide_bitmask>65535</collide_bitmask>
              <ode/>
            </contact>
            <friction>
              <ode>
                <mu>100</mu>
                <mu2>50</mu2>
              </ode>
              <torsional>
                <ode/>
              </torsional>
            </friction>
            <bounce/>
          </surface>
          <max_contacts>10</max_contacts>
        </collision>
        <visual name='visual'>
          <cast_shadows>0</cast_shadows>
          <geometry>
            <plane>
              <normal>0 0 1</normal>
              <size>100 100</size>
            </plane>
          </geometry>
          <material>
            <script>
              <uri>file://media/materials/scripts/gazebo.material</uri>
              <name>Gazebo/Grey</name>
            </script>
          </material>
        </visual>
        <self_collide>0</self_collide>
        <enable_wind>0</enable_wind>
        <kinematic>0</kinematic>
      </link>
      <pose>1.17331 -0.156415 0 0 -0 0</pose>
    </model>
    <model name='lab table'>
      <static>1</static>
      <link name='link'>
        <collision name='colision'>
          <pose>0 0 0 0 -0 0</pose>
          <geometry>
            <mesh>
              <uri>model://lab_table/meshes/lab_table.min.dae</uri>
              <scale>1 1 1</scale>
            </mesh>
          </geometry>
          <surface>
            <bounce/>
            <friction>
              <ode/>
              <torsional>
                <ode/>
              </torsional>
            </friction>
            <contact>
              <ode/>
            </contact>
          </surface>
          <max_contacts>10</max_contacts>
        </collision>
        <visual name='visual'>
          <pose>0 0 0 0 -0 0</pose>
          <geometry>
            <mesh>
              <uri>model://lab_table/meshes/lab_table.dae</uri>
              <scale>1 1 1</scale>
            </mesh>
          </geometry>
        </visual>
        <velocity_decay>
          <linear>0</linear>
          <angular>0</angular>
        </velocity_decay>
        <self_collide>0</self_collide>
        <kinematic>0</kinematic>
        <gravity>1</gravity>
        <enable_wind>0</enable_wind>
      </link>
      <pose>2.2531 4.5384 0 0 -0 0</pose>
    </model>
    <model name='cabinet'>
      <static>1</static>
      <link name='cabinet_bottom_plate'>
        <inertial>
          <pose>0 0 -1 0 -0 0</pose>
          <inertia>
            <ixx>2.05</ixx>
            <ixy>0</ixy>
            <ixz>0</ixz>
            <iyy>2.05</iyy>
            <iyz>0</iyz>
            <izz>2.05</izz>
          </inertia>
          <mass>25</mass>
        </inertial>
        <collision name='cabinet_bottom_plate_geom'>
          <pose>0 0 0.01 0 -0 0</pose>
          <geometry>
            <box>
              <size>0.45 0.45 0.02</size>
            </box>
          </geometry>
          <surface>
            <bounce/>
            <friction>
              <ode/>
              <torsional>
                <ode/>
              </torsional>
            </friction>
            <contact>
              <ode/>
            </contact>
          </surface>
          <max_contacts>10</max_contacts>
        </collision>
        <visual name='cabinet_bottom_plate_geom_visual'>
          <pose>0 0 0.01 0 -0 0</pose>
          <geometry>
            <box>
              <size>0.45 0.45 0.02</size>
            </box>
          </geometry>
          <material>
            <script>
              <uri>file://media/materials/scripts/gazebo.material</uri>
              <name>Gazebo/Wood</name>
            </script>
          </material>
        </visual>
        <collision name='cabinet_bottom_plate_geom_cabinet_back_plate'>
          <pose>0.235 0 0.51 0 -0 0</pose>
          <geometry>
            <box>
              <size>0.02 0.45 1.02</size>
            </box>
          </geometry>
          <surface>
            <bounce/>
            <friction>
              <ode/>
              <torsional>
                <ode/>
              </torsional>
            </friction>
            <contact>
              <ode/>
            </contact>
          </surface>
          <max_contacts>10</max_contacts>
        </collision>
        <visual name='cabinet_bottom_plate_geom_cabinet_back_plate_visual'>
          <pose>0.235 0 0.51 0 -0 0</pose>
          <geometry>
            <box>
              <size>0.02 0.45 1.02</size>
            </box>
          </geometry>
          <material>
            <script>
              <uri>file://media/materials/scripts/gazebo.material</uri>
              <name>Gazebo/Wood</name>
            </script>
          </material>
        </visual>
        <collision name='cabinet_bottom_plate_geom_cabinet_left_plate'>
          <pose>0 0.235 0.51 0 -0 0</pose>
          <geometry>
            <box>
              <size>0.45 0.02 1.02</size>
            </box>
          </geometry>
          <surface>
            <bounce/>
            <friction>
              <ode/>
              <torsional>
                <ode/>
              </torsional>
            </friction>
            <contact>
              <ode/>
            </contact>
          </surface>
          <max_contacts>10</max_contacts>
        </collision>
        <visual name='cabinet_bottom_plate_geom_cabinet_left_plate_visual'>
          <pose>0 0.235 0.51 0 -0 0</pose>
          <geometry>
            <box>
              <size>0.45 0.02 1.02</size>
            </box>
          </geometry>
          <material>
            <script>
              <uri>file://media/materials/scripts/gazebo.material</uri>
              <name>Gazebo/Wood</name>
            </script>
          </material>
        </visual>
        <collision name='cabinet_bottom_plate_geom_cabinet_middle_plate'>
          <pose>0 0 0.51 0 -0 0</pose>
          <geometry>
            <box>
              <size>0.45 0.45 0.02</size>
            </box>
          </geometry>
          <surface>
            <bounce/>
            <friction>
              <ode/>
              <torsional>
                <ode/>
              </torsional>
            </friction>
            <contact>
              <ode/>
            </contact>
          </surface>
          <max_contacts>10</max_contacts>
        </collision>
        <visual name='cabinet_bottom_plate_geom_cabinet_middle_plate_visual'>
          <pose>0 0 0.51 0 -0 0</pose>
          <geometry>
            <box>
              <size>0.45 0.45 0.02</size>
            </box>
          </geometry>
          <material>
            <script>
              <uri>file://media/materials/scripts/gazebo.material</uri>
              <name>Gazebo/Wood</name>
            </script>
          </material>
        </visual>
        <collision name='cabinet_bottom_plate_geom_cabinet_right_plate'>
          <pose>0 -0.235 0.51 0 -0 0</pose>
          <geometry>
            <box>
              <size>0.45 0.02 1.02</size>
            </box>
          </geometry>
          <surface>
            <bounce/>
            <friction>
              <ode/>
              <torsional>
                <ode/>
              </torsional>
            </friction>
            <contact>
              <ode/>
            </contact>
          </surface>
          <max_contacts>10</max_contacts>
        </collision>
        <visual name='cabinet_bottom_plate_geom_cabinet_right_plate_visual'>
          <pose>0 -0.235 0.51 0 -0 0</pose>
          <geometry>
            <box>
              <size>0.45 0.02 1.02</size>
            </box>
          </geometry>
          <material>
            <script>
              <uri>file://media/materials/scripts/gazebo.material</uri>
              <name>Gazebo/Wood</name>
            </script>
          </material>
        </visual>
        <collision name='cabinet_bottom_plate_geom_cabinet_top_plate'>
          <pose>0 0 1.01 0 -0 0</pose>
          <geometry>
            <box>
              <size>0.45 0.45 0.02</size>
            </box>
          </geometry>
          <surface>
            <bounce/>
            <friction>
              <ode/>
              <torsional>
                <ode/>
              </torsional>
            </friction>
            <contact>
              <ode/>
            </contact>
          </surface>
          <max_contacts>10</max_contacts>
        </collision>
        <visual name='cabinet_bottom_plate_geom_cabinet_top_plate_visual'>
          <pose>0 0 1.01 0 -0 0</pose>
          <geometry>
            <box>
              <size>0.45 0.45 0.02</size>
            </box>
          </geometry>
          <material>
            <script>
              <uri>file://media/materials/scripts/gazebo.material</uri>
              <name>Gazebo/Wood</name>
            </script>
          </material>
        </visual>
        <velocity_decay>
          <linear>0</linear>
          <angular>0</angular>
        </velocity_decay>
        <self_collide>0</self_collide>
        <kinematic>0</kinematic>
        <gravity>1</gravity>
        <enable_wind>0</enable_wind>
      </link>
      <pose>4.57898 0.977899 0 0 -0 0</pose>
    </model>
    <model name='ikea_urban_chair'>
      <link name='link'>
        <inertial>
          <mass>10</mass>
          <inertia>
            <ixx>0</ixx>
            <ixy>0</ixy>
            <ixz>0</ixz>
            <iyy>0</iyy>
            <iyz>0</iyz>
            <izz>0.1</izz>
          </inertia>
          <pose>0 0 0 0 -0 0</pose>
        </inertial>
        <collision name='collision'>
          <pose>0 0 0 0 -0 1.6</pose>
          <geometry>
            <mesh>
              <uri>model://ikea_urban_chair/meshes/mesh.dae</uri>
            </mesh>
          </geometry>
          <max_contacts>10</max_contacts>
          <surface>
            <contact>
              <ode/>
            </contact>
            <bounce/>
            <friction>
              <torsional>
                <ode/>
              </torsional>
              <ode/>
            </friction>
          </surface>
        </collision>
        <visual name='visual'>
          <pose>0 0 0 0 -0 1.6</pose>
          <geometry>
            <mesh>
              <uri>model://ikea_urban_chair/meshes/mesh.dae</uri>
            </mesh>
          </geometry>
        </visual>
        <self_collide>0</self_collide>
        <enable_wind>0</enable_wind>
        <kinematic>0</kinematic>
      </link>
      <pose>4.20539 0.254088 0 0 -0 0</pose>
    </model>
    <model name='ikea_urban_chair_0'>
      <link name='link'>
        <inertial>
          <mass>10</mass>
          <inertia>
            <ixx>0</ixx>
            <ixy>0</ixy>
            <ixz>0</ixz>
            <iyy>0</iyy>
            <iyz>0</iyz>
            <izz>0.1</izz>
          </inertia>
          <pose>0 0 0 0 -0 0</pose>
        </inertial>
        <collision name='collision'>
          <pose>0 0 0 0 -0 1.6</pose>
          <geometry>
            <mesh>
              <uri>model://ikea_urban_chair/meshes/mesh.dae</uri>
            </mesh>
          </geometry>
          <max_contacts>10</max_contacts>
          <surface>
            <contact>
              <ode/>
            </contact>
            <bounce/>
            <friction>
              <torsional>
                <ode/>
              </torsional>
              <ode/>
            </friction>
          </surface>
        </collision>
        <visual name='visual'>
          <pose>0 0 0 0 -0 1.6</pose>
          <geometry>
            <mesh>
              <uri>model://ikea_urban_chair/meshes/mesh.dae</uri>
            </mesh>
          </geometry>
        </visual>
        <self_collide>0</self_collide>
        <enable_wind>0</enable_wind>
        <kinematic>0</kinematic>
      </link>
      <pose>4.18534 -0.638003 0 0 -0 0</pose>
    </model>
    <model name='bookshelf'>
      <static>1</static>
      <link name='link'>
        <inertial>
          <mass>1</mass>
        </inertial>
        <collision name='back'>
          <pose>0 0.005 0.6 0 -0 0</pose>
          <geometry>
            <box>
              <size>0.9 0.01 1.2</size>
            </box>
          </geometry>
          <surface>
            <bounce/>
            <friction>
              <ode/>
              <torsional>
                <ode/>
              </torsional>
            </friction>
            <contact>
              <ode/>
            </contact>
          </surface>
          <max_contacts>10</max_contacts>
        </collision>
        <visual name='visual1'>
          <pose>0 0.005 0.6 0 -0 0</pose>
          <geometry>
            <box>
              <size>0.9 0.01 1.2</size>
            </box>
          </geometry>
          <material>
            <script>
              <uri>file://media/materials/scripts/gazebo.material</uri>
              <name>Gazebo/Wood</name>
            </script>
          </material>
        </visual>
        <collision name='left_side'>
          <pose>0.45 -0.195 0.6 0 -0 0</pose>
          <geometry>
            <box>
              <size>0.02 0.4 1.2</size>
            </box>
          </geometry>
          <surface>
            <bounce/>
            <friction>
              <ode/>
              <torsional>
                <ode/>
              </torsional>
            </friction>
            <contact>
              <ode/>
            </contact>
          </surface>
          <max_contacts>10</max_contacts>
        </collision>
        <visual name='visual2'>
          <pose>0.45 -0.195 0.6 0 -0 0</pose>
          <geometry>
            <box>
              <size>0.02 0.4 1.2</size>
            </box>
          </geometry>
          <material>
            <script>
              <uri>file://media/materials/scripts/gazebo.material</uri>
              <name>Gazebo/Wood</name>
            </script>
          </material>
        </visual>
        <collision name='right_side'>
          <pose>-0.45 -0.195 0.6 0 -0 0</pose>
          <geometry>
            <box>
              <size>0.02 0.4 1.2</size>
            </box>
          </geometry>
          <surface>
            <bounce/>
            <friction>
              <ode/>
              <torsional>
                <ode/>
              </torsional>
            </friction>
            <contact>
              <ode/>
            </contact>
          </surface>
          <max_contacts>10</max_contacts>
        </collision>
        <visual name='visual3'>
          <pose>-0.45 -0.195 0.6 0 -0 0</pose>
          <geometry>
            <box>
              <size>0.02 0.4 1.2</size>
            </box>
          </geometry>
          <material>
            <script>
              <uri>file://media/materials/scripts/gazebo.material</uri>
              <name>Gazebo/Wood</name>
            </script>
          </material>
        </visual>
        <collision name='bottom'>
          <pose>0 -0.195 0.03 0 -0 0</pose>
          <geometry>
            <box>
              <size>0.88 0.4 0.06</size>
            </box>
          </geometry>
          <surface>
            <bounce/>
            <friction>
              <ode/>
              <torsional>
                <ode/>
              </torsional>
            </friction>
            <contact>
              <ode/>
            </contact>
          </surface>
          <max_contacts>10</max_contacts>
        </collision>
        <visual name='visual4'>
          <pose>0 -0.195 0.03 0 -0 0</pose>
          <geometry>
            <box>
              <size>0.88 0.4 0.06</size>
            </box>
          </geometry>
          <material>
            <script>
              <uri>file://media/materials/scripts/gazebo.material</uri>
              <name>Gazebo/Wood</name>
            </script>
          </material>
        </visual>
        <collision name='top'>
          <pose>0 -0.195 1.19 0 -0 0</pose>
          <geometry>
            <box>
              <size>0.88 0.4 0.02</size>
            </box>
          </geometry>
          <surface>
            <bounce/>
            <friction>
              <ode/>
              <torsional>
                <ode/>
              </torsional>
            </friction>
            <contact>
              <ode/>
            </contact>
          </surface>
          <max_contacts>10</max_contacts>
        </collision>
        <visual name='visual5'>
          <pose>0 -0.195 1.19 0 -0 0</pose>
          <geometry>
            <box>
              <size>0.88 0.4 0.02</size>
            </box>
          </geometry>
          <material>
            <script>
              <uri>file://media/materials/scripts/gazebo.material</uri>
              <name>Gazebo/Wood</name>
            </script>
          </material>
        </visual>
        <collision name='low_shelf'>
          <pose>0 -0.195 0.43 0 -0 0</pose>
          <geometry>
            <box>
              <size>0.88 0.4 0.02</size>
            </box>
          </geometry>
          <surface>
            <bounce/>
            <friction>
              <ode/>
              <torsional>
                <ode/>
              </torsional>
            </friction>
            <contact>
              <ode/>
            </contact>
          </surface>
          <max_contacts>10</max_contacts>
        </collision>
        <visual name='visual6'>
          <pose>0 -0.195 0.43 0 -0 0</pose>
          <geometry>
            <box>
              <size>0.88 0.4 0.02</size>
            </box>
          </geometry>
          <material>
            <script>
              <uri>file://media/materials/scripts/gazebo.material</uri>
              <name>Gazebo/Wood</name>
            </script>
          </material>
        </visual>
        <collision name='high_shelf'>
          <pose>0 -0.195 0.8 0 -0 0</pose>
          <geometry>
            <box>
              <size>0.88 0.4 0.02</size>
            </box>
          </geometry>
          <surface>
            <bounce/>
            <friction>
              <ode/>
              <torsional>
                <ode/>
              </torsional>
            </friction>
            <contact>
              <ode/>
            </contact>
          </surface>
          <max_contacts>10</max_contacts>
        </collision>
        <visual name='visual7'>
          <pose>0 -0.195 0.8 0 -0 0</pose>
          <geometry>
            <box>
              <size>0.88 0.4 0.02</size>
            </box>
          </geometry>
          <material>
            <script>
              <uri>file://media/materials/scripts/gazebo.material</uri>
              <name>Gazebo/Wood</name>
            </script>
          </material>
        </visual>
        <velocity_decay>
          <linear>0</linear>
          <angular>0</angular>
        </velocity_decay>
        <self_collide>0</self_collide>
        <kinematic>0</kinematic>
        <gravity>1</gravity>
        <enable_wind>0</enable_wind>
      </link>
      <pose>-7.32653 1.17165 0 0 -0 0</pose>
    </model>
    <model name='bookshelf_0'>
      <static>1</static>
      <link name='link'>
        <inertial>
          <mass>1</mass>
        </inertial>
        <collision name='back'>
          <pose>0 0.005 0.6 0 -0 0</pose>
          <geometry>
            <box>
              <size>0.9 0.01 1.2</size>
            </box>
          </geometry>
          <surface>
            <bounce/>
            <friction>
              <ode/>
              <torsional>
                <ode/>
              </torsional>
            </friction>
            <contact>
              <ode/>
            </contact>
          </surface>
          <max_contacts>10</max_contacts>
        </collision>
        <visual name='visual1'>
          <pose>0 0.005 0.6 0 -0 0</pose>
          <geometry>
            <box>
              <size>0.9 0.01 1.2</size>
            </box>
          </geometry>
          <material>
            <script>
              <uri>file://media/materials/scripts/gazebo.material</uri>
              <name>Gazebo/Wood</name>
            </script>
          </material>
        </visual>
        <collision name='left_side'>
          <pose>0.45 -0.195 0.6 0 -0 0</pose>
          <geometry>
            <box>
              <size>0.02 0.4 1.2</size>
            </box>
          </geometry>
          <surface>
            <bounce/>
            <friction>
              <ode/>
              <torsional>
                <ode/>
              </torsional>
            </friction>
            <contact>
              <ode/>
            </contact>
          </surface>
          <max_contacts>10</max_contacts>
        </collision>
        <visual name='visual2'>
          <pose>0.45 -0.195 0.6 0 -0 0</pose>
          <geometry>
            <box>
              <size>0.02 0.4 1.2</size>
            </box>
          </geometry>
          <material>
            <script>
              <uri>file://media/materials/scripts/gazebo.material</uri>
              <name>Gazebo/Wood</name>
            </script>
          </material>
        </visual>
        <collision name='right_side'>
          <pose>-0.45 -0.195 0.6 0 -0 0</pose>
          <geometry>
            <box>
              <size>0.02 0.4 1.2</size>
            </box>
          </geometry>
          <surface>
            <bounce/>
            <friction>
              <ode/>
              <torsional>
                <ode/>
              </torsional>
            </friction>
            <contact>
              <ode/>
            </contact>
          </surface>
          <max_contacts>10</max_contacts>
        </collision>
        <visual name='visual3'>
          <pose>-0.45 -0.195 0.6 0 -0 0</pose>
          <geometry>
            <box>
              <size>0.02 0.4 1.2</size>
            </box>
          </geometry>
          <material>
            <script>
              <uri>file://media/materials/scripts/gazebo.material</uri>
              <name>Gazebo/Wood</name>
            </script>
          </material>
        </visual>
        <collision name='bottom'>
          <pose>0 -0.195 0.03 0 -0 0</pose>
          <geometry>
            <box>
              <size>0.88 0.4 0.06</size>
            </box>
          </geometry>
          <surface>
            <bounce/>
            <friction>
              <ode/>
              <torsional>
                <ode/>
              </torsional>
            </friction>
            <contact>
              <ode/>
            </contact>
          </surface>
          <max_contacts>10</max_contacts>
        </collision>
        <visual name='visual4'>
          <pose>0 -0.195 0.03 0 -0 0</pose>
          <geometry>
            <box>
              <size>0.88 0.4 0.06</size>
            </box>
          </geometry>
          <material>
            <script>
              <uri>file://media/materials/scripts/gazebo.material</uri>
              <name>Gazebo/Wood</name>
            </script>
          </material>
        </visual>
        <collision name='top'>
          <pose>0 -0.195 1.19 0 -0 0</pose>
          <geometry>
            <box>
              <size>0.88 0.4 0.02</size>
            </box>
          </geometry>
          <surface>
            <bounce/>
            <friction>
              <ode/>
              <torsional>
                <ode/>
              </torsional>
            </friction>
            <contact>
              <ode/>
            </contact>
          </surface>
          <max_contacts>10</max_contacts>
        </collision>
        <visual name='visual5'>
          <pose>0 -0.195 1.19 0 -0 0</pose>
          <geometry>
            <box>
              <size>0.88 0.4 0.02</size>
            </box>
          </geometry>
          <material>
            <script>
              <uri>file://media/materials/scripts/gazebo.material</uri>
              <name>Gazebo/Wood</name>
            </script>
          </material>
        </visual>
        <collision name='low_shelf'>
          <pose>0 -0.195 0.43 0 -0 0</pose>
          <geometry>
            <box>
              <size>0.88 0.4 0.02</size>
            </box>
          </geometry>
          <surface>
            <bounce/>
            <friction>
              <ode/>
              <torsional>
                <ode/>
              </torsional>
            </friction>
            <contact>
              <ode/>
            </contact>
          </surface>
          <max_contacts>10</max_contacts>
        </collision>
        <visual name='visual6'>
          <pose>0 -0.195 0.43 0 -0 0</pose>
          <geometry>
            <box>
              <size>0.88 0.4 0.02</size>
            </box>
          </geometry>
          <material>
            <script>
              <uri>file://media/materials/scripts/gazebo.material</uri>
              <name>Gazebo/Wood</name>
            </script>
          </material>
        </visual>
        <collision name='high_shelf'>
          <pose>0 -0.195 0.8 0 -0 0</pose>
          <geometry>
            <box>
              <size>0.88 0.4 0.02</size>
            </box>
          </geometry>
          <surface>
            <bounce/>
            <friction>
              <ode/>
              <torsional>
                <ode/>
              </torsional>
            </friction>
            <contact>
              <ode/>
            </contact>
          </surface>
          <max_contacts>10</max_contacts>
        </collision>
        <visual name='visual7'>
          <pose>0 -0.195 0.8 0 -0 0</pose>
          <geometry>
            <box>
              <size>0.88 0.4 0.02</size>
            </box>
          </geometry>
          <material>
            <script>
              <uri>file://media/materials/scripts/gazebo.material</uri>
              <name>Gazebo/Wood</name>
            </script>
          </material>
        </visual>
        <velocity_decay>
          <linear>0</linear>
          <angular>0</angular>
        </velocity_decay>
        <self_collide>0</self_collide>
        <kinematic>0</kinematic>
        <gravity>1</gravity>
        <enable_wind>0</enable_wind>
      </link>
      <pose>-6.31017 1.17165 0 0 -0 0</pose>
    </model>
    <state world_name='corridor'>
      <sim_time>737 818000000</sim_time>
      <real_time>155 506625091</real_time>
      <wall_time>1776861610 871958227</wall_time>
      <iterations>368858</iterations>
      <model name='0'>
        <pose>-0.385797 -0.836245 0.75 0 -0 1.11234</pose>
        <scale>1 1 1</scale>
        <link name='link'>
          <pose>-0.385797 -0.836245 0.75 0 -0 1.11234</pose>
          <velocity>0 0 0 0 -0 0</velocity>
          <acceleration>0 0 -0.49 0 -0 0</acceleration>
          <wrench>0 0 -9.8 0 -0 0</wrench>
        </link>
      </model>
      <model name='1'>
        <pose>0.761768 -0.154471 0.75 0 -0 1.19108</pose>
        <scale>1 1 1</scale>
        <link name='link'>
          <pose>0.761768 -0.154471 0.75 0 -0 1.19108</pose>
          <velocity>0 0 0 0 -0 0</velocity>
          <acceleration>0 0 -0.49 0 -0 0</acceleration>
          <wrench>0 0 -9.8 0 -0 0</wrench>
        </link>
      </model>
      <model name='2'>
        <pose>-0.279608 -2.53221 0.75 0 0 -1.13627</pose>
        <scale>1 1 1</scale>
        <link name='link'>
          <pose>-0.279608 -2.53221 0.75 0 0 -1.13627</pose>
          <velocity>0 0 0 0 -0 0</velocity>
          <acceleration>0 0 -0.49 0 -0 0</acceleration>
          <wrench>0 0 -9.8 0 -0 0</wrench>
        </link>
      </model>
      <model name='3'>
        <pose>0.511425 -1.72712 0.75 0 -0 2.40341</pose>
        <scale>1 1 1</scale>
        <link name='link'>
          <pose>0.511425 -1.72712 0.75 0 -0 2.40341</pose>
          <velocity>0 0 0 0 -0 0</velocity>
          <acceleration>0 0 -0.49 0 -0 0</acceleration>
          <wrench>0 0 -9.8 0 -0 0</wrench>
        </link>
      </model>
      <model name='bookshelf'>
        <pose>-7.32653 1.17165 0 0 -0 0</pose>
        <scale>1 1 1</scale>
        <link name='link'>
          <pose>-7.32653 1.17165 0 0 -0 0</pose>
          <velocity>0 0 0 0 -0 0</velocity>
          <acceleration>0 0 0 0 -0 0</acceleration>
          <wrench>0 0 0 0 -0 0</wrench>
        </link>
      </model>
      <model name='bookshelf_0'>
        <pose>-6.31017 1.17165 0 0 -0 0</pose>
        <scale>1 1 1</scale>
        <link name='link'>
          <pose>-6.31017 1.17165 0 0 -0 0</pose>
          <velocity>0 0 0 0 -0 0</velocity>
          <acceleration>0 0 0 0 -0 0</acceleration>
          <wrench>0 0 0 0 -0 0</wrench>
        </link>
      </model>
      <model name='cabinet'>
        <pose>4.59902 0.950196 0 0 -0 0</pose>
        <scale>1 1 1</scale>
        <link name='cabinet_bottom_plate'>
          <pose>4.59902 0.950196 0 0 -0 0</pose>
          <velocity>0 0 0 0 -0 0</velocity>
          <acceleration>0 0 0 0 -0 0</acceleration>
          <wrench>0 0 0 0 -0 0</wrench>
        </link>
      </model>
      <model name='ground_plane'>
        <pose>1.17331 -0.156415 0 0 -0 0</pose>
        <scale>1 1 1</scale>
        <link name='link'>
          <pose>1.17331 -0.156415 0 0 -0 0</pose>
          <velocity>0 0 0 0 -0 0</velocity>
          <acceleration>0 0 0 0 -0 0</acceleration>
          <wrench>0 0 0 0 -0 0</wrench>
        </link>
      </model>
      <model name='ikea_urban_chair'>
        <pose>4.33809 0.004139 0.023918 -1e-06 3.8e-05 -0.003294</pose>
        <scale>1 1 1</scale>
        <link name='link'>
          <pose>4.33809 0.004139 0.023918 -1e-06 3.8e-05 -0.003294</pose>
          <velocity>0 0 0 0 -0 0</velocity>
          <acceleration>0.442667 0.010866 -2.08717 -0.000256 0.009185 -0</acceleration>
          <wrench>4.42667 0.108663 -20.8717 0 -0 0</wrench>
        </link>
      </model>
      <model name='ikea_urban_chair_0'>
        <pose>4.35551 -0.660834 0.023925 -0 -8e-06 0.000103</pose>
        <scale>1 1 1</scale>
        <link name='link'>
          <pose>4.35551 -0.660834 0.023925 -0 -8e-06 0.000103</pose>
          <velocity>0 0 0 0 -0 0</velocity>
          <acceleration>-0.661551 -0.018488 1.62161 3.03407 -0.414815 3.14159</acceleration>
          <wrench>-6.61551 -0.184879 16.2161 0 -0 0</wrench>
        </link>
      </model>
      <model name='lab table'>
        <pose>4.54222 -0.29266 0 0 0 -1.567</pose>
        <scale>1 1 1</scale>
        <link name='link'>
          <pose>4.54222 -0.29266 0 0 0 -1.567</pose>
          <velocity>0 0 0 0 -0 0</velocity>
          <acceleration>0 0 0 0 -0 0</acceleration>
          <wrench>0 0 0 0 -0 0</wrench>
        </link>
      </model>
      <model name='4'>
      <link name='link'>
        <kinematic>1</kinematic>
        <inertial>
          <mass>20</mass>
          <inertia><ixx>0</ixx><ixy>0</ixy><ixz>0</ixz><iyy>0</iyy><iyz>0</iyz><izz>0</izz></inertia>
          <pose>0 0 0 0 -0 0</pose>
        </inertial>
        <collision name='collision'>
          <pose>0 0 0 0 -0 1.5708</pose>
          <geometry><mesh><uri>model://citizen_extras_female_02/meshes/mesh.dae</uri></mesh></geometry>
          <max_contacts>10</max_contacts>
          <surface><contact><ode/></contact><bounce/><friction><torsional><ode/></torsional><ode/></friction></surface>
        </collision>
        <visual name='visual'>
          <pose>0 0 0 0 -0 1.5708</pose>
          <geometry><mesh><uri>model://citizen_extras_female_02/meshes/mesh.dae</uri></mesh></geometry>
        </visual>
        <self_collide>0</self_collide>
        <enable_wind>0</enable_wind>
      </link>
      <pose>0.3 0.0 0 0 -0 0</pose>
    </model>
    <model name='5'>
      <link name='link'>
        <kinematic>1</kinematic>
        <inertial>
          <mass>20</mass>
          <inertia><ixx>0</ixx><ixy>0</ixy><ixz>0</ixz><iyy>0</iyy><iyz>0</iyz><izz>0</izz></inertia>
          <pose>0 0 0 0 -0 0</pose>
        </inertial>
        <collision name='collision'>
          <pose>0 0 0 0 -0 1.5708</pose>
          <geometry><mesh><uri>model://citizen_extras_female_03/meshes/mesh.dae</uri></mesh></geometry>
          <max_contacts>10</max_contacts>
          <surface><contact><ode/></contact><bounce/><friction><torsional><ode/></torsional><ode/></friction></surface>
        </collision>
        <visual name='visual'>
          <pose>0 0 0 0 -0 1.5708</pose>
          <geometry><mesh><uri>model://citizen_extras_female_03/meshes/mesh.dae</uri></mesh></geometry>
        </visual>
        <self_collide>0</self_collide>
        <enable_wind>0</enable_wind>
      </link>
      <pose>-0.3 0.1 0 0 -0 0</pose>
    </model>
    <model name='6'>
      <link name='link'>
        <kinematic>1</kinematic>
        <inertial>
          <mass>20</mass>
          <inertia><ixx>0</ixx><ixy>0</ixy><ixz>0</ixz><iyy>0</iyy><iyz>0</iyz><izz>0</izz></inertia>
          <pose>0 0 0 0 -0 0</pose>
        </inertial>
        <collision name='collision'>
          <pose>0 0 0 0 -0 1.5708</pose>
          <geometry><mesh><uri>model://citizen_extras_male_03/meshes/mesh.dae</uri></mesh></geometry>
          <max_contacts>10</max_contacts>
          <surface><contact><ode/></contact><bounce/><friction><torsional><ode/></torsional><ode/></friction></surface>
        </collision>
        <visual name='visual'>
          <pose>0 0 0 0 -0 1.5708</pose>
          <geometry><mesh><uri>model://citizen_extras_male_03/meshes/mesh.dae</uri></mesh></geometry>
        </visual>
        <self_collide>0</self_collide>
        <enable_wind>0</enable_wind>
      </link>
      <pose>0.1 -0.2 0 0 -0 0</pose>
    </model>
    <model name='7'>
      <link name='link'>
        <kinematic>1</kinematic>
        <inertial>
          <mass>20</mass>
          <inertia><ixx>0</ixx><ixy>0</ixy><ixz>0</ixz><iyy>0</iyy><iyz>0</iyz><izz>0</izz></inertia>
          <pose>0 0 0 0 -0 0</pose>
        </inertial>
        <collision name='collision'>
          <pose>0 0 0 0 -0 1.5708</pose>
          <geometry><mesh><uri>model://citizen_extras_female_02/meshes/mesh.dae</uri></mesh></geometry>
          <max_contacts>10</max_contacts>
          <surface><contact><ode/></contact><bounce/><friction><torsional><ode/></torsional><ode/></friction></surface>
        </collision>
        <visual name='visual'>
          <pose>0 0 0 0 -0 1.5708</pose>
          <geometry><mesh><uri>model://citizen_extras_female_02/meshes/mesh.dae</uri></mesh></geometry>
        </visual>
        <self_collide>0</self_collide>
        <enable_wind>0</enable_wind>
      </link>
      <pose>-0.1 0.2 0 0 -0 0</pose>
    </model>
    <model name='poster_0'>
        <pose>3.89372 5.77585 0 0 -0 0</pose>
        <scale>1 1 1</scale>
        <link name='Wall_0'>
          <pose>-0.86668 1.28894 0 0 -0 0</pose>
          <velocity>0 0 0 0 -0 0</velocity>
          <acceleration>0 0 0 0 -0 0</acceleration>
          <wrench>0 0 0 0 -0 0</wrench>
        </link>
      </model>
      <model name='poster_1'>
        <pose>5.53727 5.77499 0 0 -0 0</pose>
        <scale>1 1 1</scale>
        <link name='Wall_0'>
          <pose>0.77687 1.28808 0 0 -0 0</pose>
          <velocity>0 0 0 0 -0 0</velocity>
          <acceleration>0 0 0 0 -0 0</acceleration>
          <wrench>0 0 0 0 -0 0</wrench>
        </link>
      </model>
      <model name='tiago'>
        <pose>-6.00194 -4e-06 -0.000971 0.000481 0.000432 0.000665</pose>
        <scale>1 1 1</scale>
        <link name='base_footprint'>
          <pose>-6.00194 -4e-06 -0.000971 0.000481 0.000432 0.000665</pose>
          <velocity>-0.000571 6.5e-05 0.000875 -0.003632 0.002497 -4e-06</velocity>
          <acceleration>0.049493 0.067421 0.379166 -0.237492 0.077898 -0.002016</acceleration>
          <wrench>2.12081 2.88901 16.2475 0 -0 0</wrench>
        </link>
        <link name='caster_back_left_1_link'>
          <pose>-6.17548 0.101849 0.06462 0.000413 0.012833 -0.079171</pose>
          <velocity>-0.000412 0.000303 0.001213 -0.002975 0.010079 0.000428</velocity>
          <acceleration>0.165332 0.008143 0.087404 -0.719872 0.048377 1.7325</acceleration>
          <wrench>0.008506 0.000419 0.004497 0 -0 0</wrench>
        </link>
        <link name='caster_back_left_2_link'>
          <pose>-6.19155 0.103143 0.024893 -1.57045 -0.363532 -0.079307</pose>
          <velocity>-0.000576 0.000155 0.001404 -0.006042 -0.023134 0.000372</velocity>
          <acceleration>0.085228 -0.007742 -0.007274 0.49585 -1.41058 1.35531</acceleration>
          <wrench>0.007548 -0.000686 -0.000644 0 -0 0</wrench>
        </link>
        <link name='caster_back_right_1_link'>
          <pose>-6.17535 -0.10215 0.064639 0.000538 0.015892 -0.309472</pose>
          <velocity>-0.000412 0.000303 0.00179 -0.002462 0.005762 -0.007723</velocity>
          <acceleration>0.1715 -0.027655 0.097792 -2.72057 -0.631361 1.34328</acceleration>
          <wrench>0.008823 -0.001423 0.005031 0 -0 0</wrench>
        </link>
        <link name='caster_back_right_2_link'>
          <pose>-6.19071 -0.097211 0.024978 -1.57028 -0.739566 -0.309858</pose>
          <velocity>-0.000502 0.000288 0.001871 -0.011215 -0.020306 -0.007813</velocity>
          <acceleration>0.078295 -0.023567 -0.009531 -1.87317 -1.24471 -1.65851</acceleration>
          <wrench>0.006934 -0.002087 -0.000844 0 -0 0</wrench>
        </link>
        <link name='caster_front_left_1_link'>
          <pose>-5.83248 0.102077 0.064527 0.000419 0.014328 -0.098896</pose>
          <velocity>-0.000424 0.0003 0.001065 -0.001115 0.02795 -0.000875</velocity>
          <acceleration>0.153698 0.006039 0.08232 -0.791255 0.649347 1.73179</acceleration>
          <wrench>0.007907 0.000311 0.004235 0 -0 0</wrench>
        </link>
        <link name='caster_front_left_2_link'>
          <pose>-5.84853 0.103689 0.024832 -1.57043 -0.520987 -0.099099</pose>
          <velocity>-0.000718 0.00019 0.00166 -0.007393 -0.028839 -0.00098</velocity>
          <acceleration>0.078936 -0.008968 -0.005792 -2.53451 -1.36032 -1.70415</acceleration>
          <wrench>0.00699 -0.000794 -0.000513 0 -0 0</wrench>
        </link>
        <link name='caster_front_right_1_link'>
          <pose>-5.83235 -0.101922 0.064558 0.000495 0.017785 -0.22291</pose>
          <velocity>-0.000414 0.0003 0.001663 0.001757 0.0249 -0.004043</velocity>
          <acceleration>0.166479 -0.013237 0.094082 -1.86163 -0.211052 1.51043</acceleration>
          <wrench>0.008565 -0.000681 0.00484 0 -0 0</wrench>
        </link>
        <link name='caster_front_right_2_link'>
          <pose>-5.8481 -0.098328 0.024938 -1.57027 -0.852878 -0.223347</pose>
          <velocity>-0.000679 0.000271 0.002174 -0.010559 -0.027335 -0.004157</velocity>
          <acceleration>0.080148 -0.017595 -0.005842 -2.11251 -1.3811 -1.57147</acceleration>
          <wrench>0.007098 -0.001558 -0.000517 0 -0 0</wrench>
        </link>
        <link name='head_1_link'>
          <pose>-5.88155 -0.000352 0.887473 0.00048 0.000428 0.000348</pose>
          <velocity>0.001991 0.003289 0.000601 -0.003629 0.001407 0.001291</velocity>
          <acceleration>0.073606 0.240421 0.367081 -0.369698 0.209051 1.10696</acceleration>
          <wrench>0.045797 0.14959 0.228398 0 -0 0</wrench>
        </link>
        <link name='head_2_link'>
          <pose>-5.87651 -0.000397 0.985466 1.57129 0.003313 0.000347</pose>
          <velocity>0.002208 0.003652 0.000495 -0.003583 0.008097 0.001348</velocity>
          <acceleration>0.08426 0.311288 0.368021 2.80232 1.14454 -0.250899</acceleration>
          <wrench>0.074733 0.276091 0.326409 0 -0 0</wrench>
        </link>
        <link name='suspension_left_link'>
          <pose>-6.0019 -5e-05 0.096345 0.000481 0.000432 0.000665</pose>
          <velocity>-0.00033 0.000417 0.000843 -0.003634 0.002504 -3e-06</velocity>
          <acceleration>0.038824 0.034959 0.022561 -0.23785 0.078099 -0.001717</acceleration>
          <wrench>0.388243 0.349588 0.225607 0 -0 0</wrench>
        </link>
        <link name='suspension_right_link'>
          <pose>-6.0019 -5e-05 0.09654 0.000481 0.000432 0.000665</pose>
          <velocity>-0.00033 0.000419 -0.00052 -0.003634 0.002505 -4e-06</velocity>
          <acceleration>0.038874 0.035067 -0.020753 -0.237669 0.077771 -0.001772</acceleration>
          <wrench>0.388738 0.350666 -0.207527 0 -0 0</wrench>
        </link>
        <link name='torso_lift_link'>
          <pose>-6.06355 -0.000472 0.887553 0.000481 0.000432 0.000665</pose>
          <velocity>0.001653 0.003295 0.001029 -0.003632 0.002499 -5e-06</velocity>
          <acceleration>0.088367 0.18617 0.380636 -0.237117 0.079362 -0.00185</acceleration>
          <wrench>0.61256 1.29053 2.63856 0 -0 0</wrench>
        </link>
        <link name='wheel_left_link'>
          <pose>-6.00203 0.202151 0.096442 -1.57028 -0.020605 0.000654</pose>
          <velocity>-0.000329 0.000404 0.000109 -0.004104 -0.003338 -5e-06</velocity>
          <acceleration>0.040726 0.03619 -0.025991 2.76822 -0.238202 3.13563</acceleration>
          <wrench>0.074269 0.065997 -0.047397 0 -0 0</wrench>
        </link>
        <link name='wheel_right_link'>
          <pose>-6.00176 -0.202249 0.096443 -1.57028 -0.017875 0.000655</pose>
          <velocity>-0.000331 0.000405 0.000213 -0.004113 -0.003358 -5e-06</velocity>
          <acceleration>0.040045 0.036233 0.027764 2.76736 -0.246016 3.13566</acceleration>
          <wrench>0.073027 0.066076 0.050631 0 -0 0</wrench>
        </link>
      </model>
      <model name='wall_bottom_left'>
        <pose>-4.675 -1.35 1.25 0 -0 0</pose>
        <scale>1 1 1</scale>
        <link name='link'>
          <pose>-4.675 -1.35 1.25 0 -0 0</pose>
          <velocity>0 0 0 0 -0 0</velocity>
          <acceleration>0 0 0 0 -0 0</acceleration>
          <wrench>0 0 0 0 -0 0</wrench>
        </link>
      </model>
      <model name='wall_bottom_right'>
        <pose>3.175 -1.35 1.25 0 -0 0</pose>
        <scale>1 1 1</scale>
        <link name='link'>
          <pose>3.175 -1.35 1.25 0 -0 0</pose>
          <velocity>0 0 0 0 -0 0</velocity>
          <acceleration>0 0 0 0 -0 0</acceleration>
          <wrench>0 0 0 0 -0 0</wrench>
        </link>
      </model>
      <model name='wall_end_left'>
        <pose>-8 0 1.25 0 -0 0</pose>
        <scale>1 1 1</scale>
        <link name='link'>
          <pose>-8 0 1.25 0 -0 0</pose>
          <velocity>0 0 0 0 -0 0</velocity>
          <acceleration>0 0 0 0 -0 0</acceleration>
          <wrench>0 0 0 0 -0 0</wrench>
        </link>
      </model>
      <model name='wall_end_right'>
        <pose>5 0 1.25 0 -0 0</pose>
        <scale>1 1 1</scale>
        <link name='link'>
          <pose>5 0 1.25 0 -0 0</pose>
          <velocity>0 0 0 0 -0 0</velocity>
          <acceleration>0 0 0 0 -0 0</acceleration>
          <wrench>0 0 0 0 -0 0</wrench>
        </link>
      </model>
      <model name='wall_top'>
        <pose>-1.5 1.35 1.25 0 -0 0</pose>
        <scale>1 1 1</scale>
        <link name='link'>
          <pose>-1.5 1.35 1.25 0 -0 0</pose>
          <velocity>0 0 0 0 -0 0</velocity>
          <acceleration>0 0 0 0 -0 0</acceleration>
          <wrench>0 0 0 0 -0 0</wrench>
        </link>
      </model>
      <model name='wall_vert_bottom'>
        <pose>0 -10 1.25 0 -0 0</pose>
        <scale>1 1 1</scale>
        <link name='link'>
          <pose>0 -10 1.25 0 -0 0</pose>
          <velocity>0 0 0 0 -0 0</velocity>
          <acceleration>0 0 0 0 -0 0</acceleration>
          <wrench>0 0 0 0 -0 0</wrench>
        </link>
      </model>
      <model name='wall_vert_left'>
        <pose>-1.35 -5.675 1.25 0 -0 0</pose>
        <scale>1 1 1</scale>
        <link name='link'>
          <pose>-1.35 -5.675 1.25 0 -0 0</pose>
          <velocity>0 0 0 0 -0 0</velocity>
          <acceleration>0 0 0 0 -0 0</acceleration>
          <wrench>0 0 0 0 -0 0</wrench>
        </link>
      </model>
      <model name='wall_vert_right'>
        <pose>1.35 -5.675 1.25 0 -0 0</pose>
        <scale>1 1 1</scale>
        <link name='link'>
          <pose>1.35 -5.675 1.25 0 -0 0</pose>
          <velocity>0 0 0 0 -0 0</velocity>
          <acceleration>0 0 0 0 -0 0</acceleration>
          <wrench>0 0 0 0 -0 0</wrench>
        </link>
      </model>
      <light name='sun'>
        <pose>0 0 10 0 -0 0</pose>
      </light>
    </state>
  </world>
</sdf>
